{
  "version": 8,
  "blockIdVersion": 11,
  "anchorX": 0,
  "anchorY": 0,
  "anchorZ": 0,
  "blocks": [
    {
      "x": -18,
      "y": 0,
      "z": -23,
      "name": "Void_Grass"
    },
    {
      "x": -18,
      "y": 0,
      "z": -22,
      "name": "Void_Grass"
    },
    {
      "x": -18,
      "y": 0,
      "z": -21,
      "name": "Rock_Magma_Cooled"
    },
    {
      "x": -17,
      "y": 0,
      "z": -24,
      "name": "Rock_Magma_Cooled"
    },
    {
      "x": -17,
      "y": 0,
      "z": -23,
      "name": "Rock_Magma_Cooled"
    },
    {
      "x": -17,
      "y": 0,
      "z": -22,
      "name": "Rock_Magma_Cooled"
    },
    {
      "x": -17,
      "y": 0,
      "z": -21,
      "name": "Rock_Magma_Cooled"
    },
    {
      "x": -17,
      "y": 0,
      "z": -20,
      "name": "Void_Grass"
    },
    {
      "x": -16,
      "y": 0,
      "z": -24,
      "name": "Rock_Magma_Cooled"
    },
    {
      "x": -16,
      "y": 0,
      "z": -23,
      "name": "Void_Grass"
    },
    {
      "x": -16,
      "y": 0,
      "z": -22,
      "name": "Rock_Magma_Cooled"
    },
    {
      "x": -16,
      "y": 0,
      "z": -21,
      "name": "Void_Grass"
    },
    {
      "x": -16,
      "y": 0,
      "z": -20,
      "name": "Void_Grass"
    },
    {
      "x": -15,
      "y": 0,
      "z": -24,
      "name": "Rock_Magma_Cooled"
    },
    {
      "x": -15,
      "y": 0,
      "z": -23,
      "name": "Void_Grass"
    },
    {
      "x": -15,
      "y": 0,
      "z": -22,
      "name": "Void_Grass"
    },
    {
      "x": -15,
      "y": 0,
      "z": -21,
      "name": "Rock_Magma_Cooled"
    },
    {
      "x": -15,
      "y": 1,
      "z": -21,
      "name": "Void_Grass"
    },
    {
      "x": -15,
      "y": 0,
      "z": -20,
      "name": "Rock_Magma_Cooled"
    },
    {
      "x": -15,
      "y": 1,
      "z": -20,
      "name": "Rock_Magma_Cooled"
    },
    {
      "x": -15,
      "y": 1,
      "z": -19,
      "name": "Rock_Magma_Cooled"
    },
    {
      "x": -14,
      "y": 0,
      "z": -24,
      "name": "Void_Grass"
    },
    {
      "x": -14,
      "y": 0,
      "z": -23,
      "name": "Rock_Magma_Cooled"
    },
    {
      "x": -14,
      "y": 0,
      "z": -22,
      "name": "Rock_Magma_Cooled"
    },
    {
      "x": -14,
      "y": 1,
      "z": -22,
      "name": "Rock_Magma_Cooled"
    },
    {
      "x": -14,
      "y": 0,
      "z": -21,
      "name": "Void_Grass"
    },
    {
      "x": -14,
      "y": 1,
      "z": -21,
      "name": "Rock_Magma_Cooled"
    },
    {
      "x": -14,
      "y": 2,
      "z": -21,
      "name": "Void_Grass"
    },
    {
      "x": -14,
      "y": 0,
      "z": -20,
      "name": "Void_Grass"
    },
    {
      "x": -14,
      "y": 1,
      "z": -20,
      "name": "Void_Grass"
    },
    {
      "x": -14,
      "y": 2,
      "z": -20,
      "name": "Void_Grass"
    },
    {
      "x": -14,
      "y": 0,
      "z": -19,
      "name": "Void_Grass"
    },
    {
      "x": -14,
      "y": 1,
      "z": -19,
      "name": "Void_Grass"
    },
    {
      "x": -14,
      "y": 2,
      "z": -19,
      "name": "Rock_Magma_Cooled"
    },
    {
      "x": -14,
      "y": 1,
      "z": -18,
      "name": "Rock_Magma_Cooled"
    },
    {
      "x": -14,
      "y": 2,
      "z": -18,
      "name": "Rock_Magma_Cooled"
    },
    {
      "x": -14,
      "y": 2,
      "z": -17,
      "name": "Rock_Magma_Cooled"
    },
    {
      "x": -13,
      "y": 0,
      "z": -25,
      "name": "Void_Grass"
    },
    {
      "x": -13,
      "y": 0,
      "z": -24,
      "name": "Rock_Magma_Cooled"
    },
    {
      "x": -13,
      "y": 0,
      "z": -23,
      "name": "Void_Grass"
    },
    {
      "x": -13,
      "y": 1,
      "z": -23,
      "name": "Rock_Magma_Cooled"
    },
    {
      "x": -13,
      "y": 0,
      "z": -22,
      "name": "Void_Grass"
    },
    {
      "x": -13,
      "y": 1,
      "z": -22,
      "name": "Rock_Magma_Cooled"
    },
    {
      "x": -13,
      "y": 2,
      "z": -22,
      "name": "Rock_Magma_Cooled"
    },
    {
      "x": -13,
      "y": 0,
      "z": -21,
      "name": "Void_Grass"
    },
    {
      "x": -13,
      "y": 1,
      "z": -21,
      "name": "Rock_Magma_Cooled"
    },
    {
      "x": -13,
      "y": 2,
      "z": -21,
      "name": "Rock_Magma_Cooled"
    },
    {
      "x": -13,
      "y": 0,
      "z": -20,
      "name": "Rock_Magma_Cooled"
    },
    {
      "x": -13,
      "y": 1,
      "z": -20,
      "name": "Void_Grass"
    },
    {
      "x": -13,
      "y": 2,
      "z": -20,
      "name": "Void_Grass"
    },
    {
      "x": -13,
      "y": 0,
      "z": -19,
      "name": "Void_Grass"
    },
    {
      "x": -13,
      "y": 1,
      "z": -19,
      "name": "Void_Grass"
    },
    {
      "x": -13,
      "y": 2,
      "z": -19,
      "name": "Void_Grass"
    },
    {
      "x": -13,
      "y": 3,
      "z": -19,
      "name": "Void_Grass"
    },
    {
      "x": -13,
      "y": 0,
      "z": -18,
      "name": "Rock_Crystal_Purple_Block"
    },
    {
      "x": -13,
      "y": 1,
      "z": -18,
      "name": "Void_Grass"
    },
    {
      "x": -13,
      "y": 2,
      "z": -18,
      "name": "Rock_Magma_Cooled"
    },
    {
      "x": -13,
      "y": 3,
      "z": -18,
      "name": "Rock_Magma_Cooled"
    },
    {
      "x": -13,
      "y": 1,
      "z": -17,
      "name": "Rock_Magma_Cooled"
    },
    {
      "x": -13,
      "y": 2,
      "z": -17,
      "name": "Void_Grass"
    },
    {
      "x": -13,
      "y": 3,
      "z": -17,
      "name": "Void_Grass"
    },
    {
      "x": -13,
      "y": 2,
      "z": -16,
      "name": "Void_Grass"
    },
    {
      "x": -12,
      "y": 0,
      "z": -26,
      "name": "Void_Grass"
    },
    {
      "x": -12,
      "y": 0,
      "z": -25,
      "name": "Void_Grass"
    },
    {
      "x": -12,
      "y": 0,
      "z": -24,
      "name": "Void_Grass"
    },
    {
      "x": -12,
      "y": 0,
      "z": -23,
      "name": "Rock_Magma_Cooled"
    },
    {
      "x": -12,
      "y": 1,
      "z": -23,
      "name": "Rock_Magma_Cooled"
    },
    {
      "x": -12,
      "y": 0,
      "z": -22,
      "name": "Void_Grass"
    },
    {
      "x": -12,
      "y": 1,
      "z": -22,
      "name": "Rock_Magma_Cooled"
    },
    {
      "x": -12,
      "y": 2,
      "z": -22,
      "name": "Void_Grass"
    },
    {
      "x": -12,
      "y": 0,
      "z": -21,
      "name": "Rock_Magma_Cooled"
    },
    {
      "x": -12,
      "y": 1,
      "z": -21,
      "name": "Rock_Magma_Cooled"
    },
    {
      "x": -12,
      "y": 2,
      "z": -21,
      "name": "Rock_Magma_Cooled"
    },
    {
      "x": -12,
      "y": 0,
      "z": -20,
      "name": "Void_Grass"
    },
    {
      "x": -12,
      "y": 1,
      "z": -20,
      "name": "Void_Grass"
    },
    {
      "x": -12,
      "y": 2,
      "z": -20,
      "name": "Void_Grass"
    },
    {
      "x": -12,
      "y": 3,
      "z": -20,
      "name": "Rock_Magma_Cooled"
    },
    {
      "x": -12,
      "y": 0,
      "z": -19,
      "name": "Rock_Magma_Cooled"
    },
    {
      "x": -12,
      "y": 1,
      "z": -19,
      "name": "Rock_Magma_Cooled"
    },
    {
      "x": -12,
      "y": 2,
      "z": -19,
      "name": "Rock_Magma_Cooled"
    },
    {
      "x": -12,
      "y": 3,
      "z": -19,
      "name": "Rock_Magma_Cooled"
    },
    {
      "x": -12,
      "y": 0,
      "z": -18,
      "name": "Rock_Magma_Cooled"
    },
    {
      "x": -12,
      "y": 1,
      "z": -18,
      "name": "Rock_Magma_Cooled"
    },
    {
      "x": -12,
      "y": 2,
      "z": -18,
      "name": "Void_Grass"
    },
    {
      "x": -12,
      "y": 3,
      "z": -18,
      "name": "Rock_Magma_Cooled"
    },
    {
      "x": -12,
      "y": 1,
      "z": -17,
      "name": "Void_Grass"
    },
    {
      "x": -12,
      "y": 2,
      "z": -17,
      "name": "Rock_Magma_Cooled"
    },
    {
      "x": -12,
      "y": 3,
      "z": -17,
      "name": "Rock_Magma_Cooled"
    },
    {
      "x": -12,
      "y": 1,
      "z": -16,
      "name": "Rock_Magma_Cooled"
    },
    {
      "x": -12,
      "y": 2,
      "z": -16,
      "name": "Void_Grass"
    },
    {
      "x": -12,
      "y": 3,
      "z": -16,
      "name": "Rock_Magma_Cooled"
    },
    {
      "x": -12,
      "y": 2,
      "z": -15,
      "name": "Void_Grass"
    },
    {
      "x": -11,
      "y": 0,
      "z": -26,
      "name": "Rock_Magma_Cooled"
    },
    {
      "x": -11,
      "y": 0,
      "z": -25,
      "name": "Void_Grass"
    },
    {
      "x": -11,
      "y": 0,
      "z": -24,
      "name": "Rock_Magma_Cooled"
    },
    {
      "x": -11,
      "y": 0,
      "z": -23,
      "name": "Void_Grass"
    },
    {
      "x": -11,
      "y": 1,
      "z": -23,
      "name": "Rock_Magma_Cooled"
    },
    {
      "x": -11,
      "y": 0,
      "z": -22,
      "name": "Void_Grass"
    },
    {
      "x": -11,
      "y": 1,
      "z": -22,
      "name": "Rock_Magma_Cooled"
    },
    {
      "x": -11,
      "y": 2,
      "z": -22,
      "name": "Rock_Magma_Cooled"
    },
    {
      "x": -11,
      "y": 0,
      "z": -21,
      "name": "Void_Grass"
    },
    {
      "x": -11,
      "y": 1,
      "z": -21,
      "name": "Rock_Magma_Cooled"
    },
    {
      "x": -11,
      "y": 2,
      "z": -21,
      "name": "Rock_Magma_Cooled"
    },
    {
      "x": -11,
      "y": 0,
      "z": -20,
      "name": "Void_Grass"
    },
    {
      "x": -11,
      "y": 1,
      "z": -20,
      "name": "Rock_Magma_Cooled"
    },
    {
      "x": -11,
      "y": 2,
      "z": -20,
      "name": "Rock_Magma_Cooled"
    },
    {
      "x": -11,
      "y": 3,
      "z": -20,
      "name": "Void_Grass"
    },
    {
      "x": -11,
      "y": 0,
      "z": -19,
      "name": "Rock_Magma_Cooled"
    },
    {
      "x": -11,
      "y": 1,
      "z": -19,
      "name": "Void_Grass"
    },
    {
      "x": -11,
      "y": 2,
      "z": -19,
      "name": "Void_Grass"
    },
    {
      "x": -11,
      "y": 3,
      "z": -19,
      "name": "Void_Grass"
    },
    {
      "x": -11,
      "y": 0,
      "z": -18,
      "name": "Void_Grass"
    },
    {
      "x": -11,
      "y": 1,
      "z": -18,
      "name": "Void_Grass"
    },
    {
      "x": -11,
      "y": 2,
      "z": -18,
      "name": "Void_Grass"
    },
    {
      "x": -11,
      "y": 3,
      "z": -18,
      "name": "Void_Grass"
    },
    {
      "x": -11,
      "y": 4,
      "z": -18,
      "name": "Rock_Magma_Cooled"
    },
    {
      "x": -11,
      "y": 1,
      "z": -17,
      "name": "Void_Grass"
    },
    {
      "x": -11,
      "y": 2,
      "z": -17,
      "name": "Void_Grass"
    },
    {
      "x": -11,
      "y": 3,
      "z": -17,
      "name": "Void_Grass"
    },
    {
      "x": -11,
      "y": 4,
      "z": -17,
      "name": "Void_Grass"
    },
    {
      "x": -11,
      "y": 1,
      "z": -16,
      "name": "Rock_Magma_Cooled"
    },
    {
      "x": -11,
      "y": 2,
      "z": -16,
      "name": "Void_Grass"
    },
    {
      "x": -11,
      "y": 3,
      "z": -16,
      "name": "Rock_Magma_Cooled"
    },
    {
      "x": -11,
      "y": 4,
      "z": -16,
      "name": "Rock_Magma_Cooled"
    },
    {
      "x": -11,
      "y": 2,
      "z": -15,
      "name": "Rock_Magma_Cooled"
    },
    {
      "x": -11,
      "y": 3,
      "z": -15,
      "name": "Void_Grass"
    },
    {
      "x": -11,
      "y": 4,
      "z": -15,
      "name": "Void_Grass"
    },
    {
      "x": -10,
      "y": 0,
      "z": -26,
      "name": "Void_Grass"
    },
    {
      "x": -10,
      "y": 0,
      "z": -25,
      "name": "Rock_Magma_Cooled"
    },
    {
      "x": -10,
      "y": 0,
      "z": -24,
      "name": "Void_Grass"
    },
    {
      "x": -10,
      "y": 0,
      "z": -23,
      "name": "Rock_Magma_Cooled"
    },
    {
      "x": -10,
      "y": 0,
      "z": -22,
      "name": "Void_Grass"
    },
    {
      "x": -10,
      "y": 1,
      "z": -22,
      "name": "Void_Grass"
    },
    {
      "x": -10,
      "y": 0,
      "z": -21,
      "name": "Rock_Magma_Cooled"
    },
    {
      "x": -10,
      "y": 1,
      "z": -21,
      "name": "Void_Grass"
    },
    {
      "x": -10,
      "y": 2,
      "z": -21,
      "name": "Void_Grass"
    },
    {
      "x": -10,
      "y": 0,
      "z": -20,
      "name": "Rock_Magma_Cooled"
    },
    {
      "x": -10,
      "y": 1,
      "z": -20,
      "name": "Void_Grass"
    },
    {
      "x": -10,
      "y": 2,
      "z": -20,
      "name": "Rock_Magma_Cooled"
    },
    {
      "x": -10,
      "y": 3,
      "z": -20,
      "name": "Void_Grass"
    },
    {
      "x": -10,
      "y": 0,
      "z": -19,
      "name": "Void_Grass"
    },
    {
      "x": -10,
      "y": 1,
      "z": -19,
      "name": "Rock_Magma_Cooled"
    },
    {
      "x": -10,
      "y": 2,
      "z": -19,
      "name": "Rock_Magma_Cooled"
    },
    {
      "x": -10,
      "y": 3,
      "z": -19,
      "name": "Void_Grass"
    },
    {
      "x": -10,
      "y": 4,
      "z": -19,
      "name": "Void_Grass"
    },
    {
      "x": -10,
      "y": 1,
      "z": -18,
      "name": "Void_Grass"
    },
    {
      "x": -10,
      "y": 2,
      "z": -18,
      "name": "Void_Grass"
    },
    {
      "x": -10,
      "y": 3,
      "z": -18,
      "name": "Rock_Magma_Cooled"
    },
    {
      "x": -10,
      "y": 4,
      "z": -18,
      "name": "Void_Grass"
    },
    {
      "x": -10,
      "y": 1,
      "z": -17,
      "name": "Void_Grass"
    },
    {
      "x": -10,
      "y": 2,
      "z": -17,
      "name": "Rock_Magma_Cooled"
    },
    {
      "x": -10,
      "y": 3,
      "z": -17,
      "name": "Rock_Magma_Cooled"
    },
    {
      "x": -10,
      "y": 4,
      "z": -17,
      "name": "Rock_Magma_Cooled"
    },
    {
      "x": -10,
      "y": 5,
      "z": -17,
      "name": "Rock_Magma_Cooled"
    },
    {
      "x": -10,
      "y": 1,
      "z": -16,
      "name": "Void_Grass"
    },
    {
      "x": -10,
      "y": 2,
      "z": -16,
      "name": "Rock_Magma_Cooled"
    },
    {
      "x": -10,
      "y": 3,
      "z": -16,
      "name": "Void_Grass"
    },
    {
      "x": -10,
      "y": 4,
      "z": -16,
      "name": "Void_Grass"
    },
    {
      "x": -10,
      "y": 5,
      "z": -16,
      "name": "Void_Grass"
    },
    {
      "x": -10,
      "y": 2,
      "z": -15,
      "name": "Void_Grass"
    },
    {
      "x": -10,
      "y": 3,
      "z": -15,
      "name": "Void_Grass"
    },
    {
      "x": -10,
      "y": 4,
      "z": -15,
      "name": "Rock_Magma_Cooled"
    },
    {
      "x": -10,
      "y": 5,
      "z": -15,
      "name": "Void_Grass"
    },
    {
      "x": -10,
      "y": 3,
      "z": -14,
      "name": "Void_Grass"
    },
    {
      "x": -10,
      "y": 4,
      "z": -14,
      "name": "Void_Grass"
    },
    {
      "x": -9,
      "y": 0,
      "z": -25,
      "name": "Rock_Magma_Cooled"
    },
    {
      "x": -9,
      "y": 0,
      "z": -24,
      "name": "Void_Grass"
    },
    {
      "x": -9,
      "y": 0,
      "z": -23,
      "name": "Rock_Magma_Cooled"
    },
    {
      "x": -9,
      "y": 1,
      "z": -21,
      "name": "Rock_Magma_Cooled"
    },
    {
      "x": -9,
      "y": 1,
      "z": -20,
      "name": "Rock_Magma_Cooled"
    },
    {
      "x": -9,
      "y": 2,
      "z": -20,
      "name": "Rock_Magma_Cooled"
    },
    {
      "x": -9,
      "y": 3,
      "z": -20,
      "name": "Void_Grass"
    },
    {
      "x": -9,
      "y": 1,
      "z": -19,
      "name": "Void_Grass"
    },
    {
      "x": -9,
      "y": 2,
      "z": -19,
      "name": "Void_Grass"
    },
    {
      "x": -9,
      "y": 3,
      "z": -19,
      "name": "Void_Grass"
    },
    {
      "x": -9,
      "y": 4,
      "z": -19,
      "name": "Rock_Magma_Cooled"
    },
    {
      "x": -9,
      "y": 1,
      "z": -18,
      "name": "Rock_Magma_Cooled"
    },
    {
      "x": -9,
      "y": 2,
      "z": -18,
      "name": "Void_Grass"
    },
    {
      "x": -9,
      "y": 3,
      "z": -18,
      "name": "Rock_Magma_Cooled"
    },
    {
      "x": -9,
      "y": 4,
      "z": -18,
      "name": "Rock_Magma_Cooled"
    },
    {
      "x": -9,
      "y": 5,
      "z": -18,
      "name": "Void_Grass"
    },
    {
      "x": -9,
      "y": 1,
      "z": -17,
      "name": "Rock_Magma_Cooled"
    },
    {
      "x": -9,
      "y": 2,
      "z": -17,
      "name": "Rock_Magma_Cooled"
    },
    {
      "x": -9,
      "y": 3,
      "z": -17,
      "name": "Rock_Magma_Cooled"
    },
    {
      "x": -9,
      "y": 4,
      "z": -17,
      "name": "Rock_Magma_Cooled"
    },
    {
      "x": -9,
      "y": 5,
      "z": -17,
      "name": "Void_Grass"
    },
    {
      "x": -9,
      "y": 2,
      "z": -16,
      "name": "Rock_Magma_Cooled"
    },
    {
      "x": -9,
      "y": 3,
      "z": -16,
      "name": "Void_Grass"
    },
    {
      "x": -9,
      "y": 4,
      "z": -16,
      "name": "Void_Grass"
    },
    {
      "x": -9,
      "y": 5,
      "z": -16,
      "name": "Void_Grass"
    },
    {
      "x": -9,
      "y": 2,
      "z": -15,
      "name": "Void_Grass"
    },
    {
      "x": -9,
      "y": 3,
      "z": -15,
      "name": "Void_Grass"
    },
    {
      "x": -9,
      "y": 4,
      "z": -15,
      "name": "Void_Grass"
    },
    {
      "x": -9,
      "y": 5,
      "z": -15,
      "name": "Rock_Magma_Cooled"
    },
    {
      "x": -9,
      "y": 3,
      "z": -14,
      "name": "Void_Grass"
    },
    {
      "x": -9,
      "y": 4,
      "z": -14,
      "name": "Rock_Magma_Cooled"
    },
    {
      "x": -9,
      "y": 5,
      "z": -14,
      "name": "Void_Grass"
    },
    {
      "x": -9,
      "y": 4,
      "z": -13,
      "name": "Rock_Magma_Cooled"
    },
    {
      "x": -8,
      "y": 3,
      "z": -20,
      "name": "Void_Grass"
    },
    {
      "x": -8,
      "y": 2,
      "z": -19,
      "name": "Void_Grass"
    },
    {
      "x": -8,
      "y": 3,
      "z": -19,
      "name": "Void_Grass"
    },
    {
      "x": -8,
      "y": 4,
      "z": -19,
      "name": "Void_Grass"
    },
    {
      "x": -8,
      "y": 2,
      "z": -18,
      "name": "Rock_Magma_Cooled"
    },
    {
      "x": -8,
      "y": 3,
      "z": -18,
      "name": "Void_Grass"
    },
    {
      "x": -8,
      "y": 4,
      "z": -18,
      "name": "Void_Grass"
    },
    {
      "x": -8,
      "y": 5,
      "z": -18,
      "name": "Rock_Magma_Cooled"
    },
    {
      "x": -8,
      "y": 2,
      "z": -17,
      "name": "Rock_Crystal_Purple_Block",
      "rotation": 4
    },
    {
      "x": -8,
      "y": 3,
      "z": -17,
      "name": "Rock_Magma_Cooled"
    },
    {
      "x": -8,
      "y": 4,
      "z": -17,
      "name": "Void_Grass"
    },
    {
      "x": -8,
      "y": 5,
      "z": -17,
      "name": "Void_Grass"
    },
    {
      "x": -8,
      "y": 2,
      "z": -16,
      "name": "Rock_Magma_Cooled"
    },
    {
      "x": -8,
      "y": 3,
      "z": -16,
      "name": "Rock_Magma_Cooled"
    },
    {
      "x": -8,
      "y": 4,
      "z": -16,
      "name": "Void_Grass"
    },
    {
      "x": -8,
      "y": 5,
      "z": -16,
      "name": "Void_Grass"
    },
    {
      "x": -8,
      "y": 6,
      "z": -16,
      "name": "Rock_Magma_Cooled"
    },
    {
      "x": -8,
      "y": 2,
      "z": -15,
      "name": "Rock_Magma_Cooled"
    },
    {
      "x": -8,
      "y": 3,
      "z": -15,
      "name": "Void_Grass"
    },
    {
      "x": -8,
      "y": 4,
      "z": -15,
      "name": "Rock_Magma_Cooled"
    },
    {
      "x": -8,
      "y": 5,
      "z": -15,
      "name": "Rock_Magma_Cooled"
    },
    {
      "x": -8,
      "y": 6,
      "z": -15,
      "name": "Void_Grass"
    },
    {
      "x": -8,
      "y": 3,
      "z": -14,
      "name": "Rock_Magma_Cooled"
    },
    {
      "x": -8,
      "y": 4,
      "z": -14,
      "name": "Void_Grass"
    },
    {
      "x": -8,
      "y": 5,
      "z": -14,
      "name": "Rock_Magma_Cooled"
    },
    {
      "x": -8,
      "y": 6,
      "z": -14,
      "name": "Void_Grass"
    },
    {
      "x": -8,
      "y": 7,
      "z": -14,
      "name": "Rock_Magma_Cooled"
    },
    {
      "x": -8,
      "y": 4,
      "z": -13,
      "name": "Void_Grass"
    },
    {
      "x": -8,
      "y": 5,
      "z": -13,
      "name": "Void_Grass"
    },
    {
      "x": -8,
      "y": 6,
      "z": -13,
      "name": "Rock_Magma_Cooled"
    },
    {
      "x": -8,
      "y": 7,
      "z": -13,
      "name": "Void_Grass"
    },
    {
      "x": -8,
      "y": 7,
      "z": -12,
      "name": "Rock_Magma_Cooled"
    },
    {
      "x": -7,
      "y": 3,
      "z": -19,
      "name": "Rock_Magma_Cooled"
    },
    {
      "x": -7,
      "y": 4,
      "z": -19,
      "name": "Rock_Magma_Cooled"
    },
    {
      "x": -7,
      "y": 2,
      "z": -18,
      "name": "Rock_Magma_Cooled"
    },
    {
      "x": -7,
      "y": 3,
      "z": -18,
      "name": "Rock_Magma_Cooled"
    },
    {
      "x": -7,
      "y": 4,
      "z": -18,
      "name": "Rock_Magma_Cooled"
    },
    {
      "x": -7,
      "y": 5,
      "z": -18,
      "name": "Void_Grass"
    },
    {
      "x": -7,
      "y": 2,
      "z": -17,
      "name": "Void_Grass"
    },
    {
      "x": -7,
      "y": 3,
      "z": -17,
      "name": "Rock_Magma_Cooled"
    },
    {
      "x": -7,
      "y": 4,
      "z": -17,
      "name": "Void_Grass"
    },
    {
      "x": -7,
      "y": 5,
      "z": -17,
      "name": "Rock_Magma_Cooled"
    },
    {
      "x": -7,
      "y": 6,
      "z": -17,
      "name": "Void_Grass"
    },
    {
      "x": -7,
      "y": 2,
      "z": -16,
      "name": "Rock_Magma_Cooled"
    },
    {
      "x": -7,
      "y": 3,
      "z": -16,
      "name": "Void_Grass"
    },
    {
      "x": -7,
      "y": 4,
      "z": -16,
      "name": "Void_Grass"
    },
    {
      "x": -7,
      "y": 5,
      "z": -16,
      "name": "Void_Grass"
    },
    {
      "x": -7,
      "y": 6,
      "z": -16,
      "name": "Void_Grass"
    },
    {
      "x": -7,
      "y": 3,
      "z": -15,
      "name": "Void_Grass"
    },
    {
      "x": -7,
      "y": 4,
      "z": -15,
      "name": "Void_Grass"
    },
    {
      "x": -7,
      "y": 5,
      "z": -15,
      "name": "Void_Grass"
    },
    {
      "x": -7,
      "y": 6,
      "z": -15,
      "name": "Void_Grass"
    },
    {
      "x": -7,
      "y": 7,
      "z": -15,
      "name": "Void_Grass"
    },
    {
      "x": -7,
      "y": 3,
      "z": -14,
      "name": "Void_Grass"
    },
    {
      "x": -7,
      "y": 4,
      "z": -14,
      "name": "Void_Grass"
    },
    {
      "x": -7,
      "y": 5,
      "z": -14,
      "name": "Void_Grass"
    },
    {
      "x": -7,
      "y": 6,
      "z": -14,
      "name": "Void_Grass"
    },
    {
      "x": -7,
      "y": 7,
      "z": -14,
      "name": "Rock_Magma_Cooled"
    },
    {
      "x": -7,
      "y": 8,
      "z": -14,
      "name": "Rock_Magma_Cooled"
    },
    {
      "x": -7,
      "y": 4,
      "z": -13,
      "name": "Rock_Crystal_Purple_Block"
    },
    {
      "x": -7,
      "y": 5,
      "z": -13,
      "name": "Void_Grass"
    },
    {
      "x": -7,
      "y": 6,
      "z": -13,
      "name": "Rock_Magma_Cooled"
    },
    {
      "x": -7,
      "y": 7,
      "z": -13,
      "name": "Rock_Magma_Cooled"
    },
    {
      "x": -7,
      "y": 8,
      "z": -13,
      "name": "Void_Grass"
    },
    {
      "x": -7,
      "y": 5,
      "z": -12,
      "name": "Rock_Magma_Cooled"
    },
    {
      "x": -7,
      "y": 6,
      "z": -12,
      "name": "Void_Grass"
    },
    {
      "x": -7,
      "y": 7,
      "z": -12,
      "name": "Void_Grass"
    },
    {
      "x": -7,
      "y": 8,
      "z": -12,
      "name": "Rock_Magma_Cooled"
    },
    {
      "x": -7,
      "y": 7,
      "z": -11,
      "name": "Rock_Magma_Cooled"
    },
    {
      "x": -7,
      "y": 8,
      "z": -11,
      "name": "Rock_Magma_Cooled"
    },
    {
      "x": -7,
      "y": 8,
      "z": -10,
      "name": "Void_Grass"
    },
    {
      "x": -6,
      "y": 3,
      "z": -18,
      "name": "Rock_Magma_Cooled"
    },
    {
      "x": -6,
      "y": 4,
      "z": -18,
      "name": "Rock_Magma_Cooled"
    },
    {
      "x": -6,
      "y": 5,
      "z": -18,
      "name": "Void_Grass"
    },
    {
      "x": -6,
      "y": 3,
      "z": -17,
      "name": "Rock_Magma_Cooled"
    },
    {
      "x": -6,
      "y": 4,
      "z": -17,
      "name": "Void_Grass"
    },
    {
      "x": -6,
      "y": 5,
      "z": -17,
      "name": "Rock_Magma_Cooled"
    },
    {
      "x": -6,
      "y": 6,
      "z": -17,
      "name": "Void_Grass"
    },
    {
      "x": -6,
      "y": 3,
      "z": -16,
      "name": "Void_Grass"
    },
    {
      "x": -6,
      "y": 4,
      "z": -16,
      "name": "Rock_Magma_Cooled"
    },
    {
      "x": -6,
      "y": 5,
      "z": -16,
      "name": "Void_Grass"
    },
    {
      "x": -6,
      "y": 6,
      "z": -16,
      "name": "Rock_Magma_Cooled"
    },
    {
      "x": -6,
      "y": 7,
      "z": -16,
      "name": "Void_Grass"
    },
    {
      "x": -6,
      "y": 3,
      "z": -15,
      "name": "Void_Grass"
    },
    {
      "x": -6,
      "y": 4,
      "z": -15,
      "name": "Void_Grass"
    },
    {
      "x": -6,
      "y": 5,
      "z": -15,
      "name": "Void_Grass"
    },
    {
      "x": -6,
      "y": 6,
      "z": -15,
      "name": "Rock_Magma_Cooled"
    },
    {
      "x": -6,
      "y": 7,
      "z": -15,
      "name": "Rock_Magma_Cooled"
    },
    {
      "x": -6,
      "y": 8,
      "z": -15,
      "name": "Rock_Magma_Cooled"
    },
    {
      "x": -6,
      "y": 4,
      "z": -14,
      "name": "Void_Grass"
    },
    {
      "x": -6,
      "y": 5,
      "z": -14,
      "name": "Rock_Magma_Cooled"
    },
    {
      "x": -6,
      "y": 6,
      "z": -14,
      "name": "Void_Grass"
    },
    {
      "x": -6,
      "y": 7,
      "z": -14,
      "name": "Void_Grass"
    },
    {
      "x": -6,
      "y": 8,
      "z": -14,
      "name": "Rock_Magma_Cooled"
    },
    {
      "x": -6,
      "y": 4,
      "z": -13,
      "name": "Rock_Magma_Cooled"
    },
    {
      "x": -6,
      "y": 5,
      "z": -13,
      "name": "Rock_Magma_Cooled"
    },
    {
      "x": -6,
      "y": 6,
      "z": -13,
      "name": "Rock_Magma_Cooled"
    },
    {
      "x": -6,
      "y": 7,
      "z": -13,
      "name": "Rock_Magma_Cooled"
    },
    {
      "x": -6,
      "y": 8,
      "z": -13,
      "name": "Void_Grass"
    },
    {
      "x": -6,
      "y": 5,
      "z": -12,
      "name": "Rock_Magma_Cooled"
    },
    {
      "x": -6,
      "y": 6,
      "z": -12,
      "name": "Rock_Magma_Cooled"
    },
    {
      "x": -6,
      "y": 7,
      "z": -12,
      "name": "Void_Grass"
    },
    {
      "x": -6,
      "y": 8,
      "z": -12,
      "name": "Rock_Magma_Cooled"
    },
    {
      "x": -6,
      "y": 9,
      "z": -12,
      "name": "Rock_Magma_Cooled"
    },
    {
      "x": -6,
      "y": 5,
      "z": -11,
      "name": "Wood_Amber_Roots"
    },
    {
      "x": -6,
      "y": 6,
      "z": -11,
      "name": "Void_Grass"
    },
    {
      "x": -6,
      "y": 7,
      "z": -11,
      "name": "Rock_Magma_Cooled"
    },
    {
      "x": -6,
      "y": 8,
      "z": -11,
      "name": "Void_Grass"
    },
    {
      "x": -6,
      "y": 9,
      "z": -11,
      "name": "Rock_Magma_Cooled"
    },
    {
      "x": -6,
      "y": 7,
      "z": -10,
      "name": "Rock_Magma_Cooled"
    },
    {
      "x": -6,
      "y": 8,
      "z": -10,
      "name": "Rock_Magma_Cooled"
    },
    {
      "x": -6,
      "y": 9,
      "z": -10,
      "name": "Rock_Magma_Cooled"
    },
    {
      "x": -6,
      "y": 8,
      "z": -9,
      "name": "Void_Grass"
    },
    {
      "x": -6,
      "y": 9,
      "z": -9,
      "name": "Rock_Magma_Cooled"
    },
    {
      "x": -6,
      "y": 12,
      "z": -7,
      "name": "Rock_Magma_Cooled"
    },
    {
      "x": -6,
      "y": 12,
      "z": -6,
      "name": "Rock_Magma_Cooled"
    },
    {
      "x": -6,
      "y": 12,
      "z": -5,
      "name": "Rock_Magma_Cooled"
    },
    {
      "x": -5,
      "y": 5,
      "z": -18,
      "name": "Void_Grass"
    },
    {
      "x": -5,
      "y": 4,
      "z": -17,
      "name": "Rock_Magma_Cooled"
    },
    {
      "x": -5,
      "y": 5,
      "z": -17,
      "name": "Rock_Magma_Cooled"
    },
    {
      "x": -5,
      "y": 6,
      "z": -17,
      "name": "Void_Grass"
    },
    {
      "x": -5,
      "y": 4,
      "z": -16,
      "name": "Rock_Magma_Cooled"
    },
    {
      "x": -5,
      "y": 5,
      "z": -16,
      "name": "Void_Grass"
    },
    {
      "x": -5,
      "y": 6,
      "z": -16,
      "name": "Void_Grass"
    },
    {
      "x": -5,
      "y": 7,
      "z": -16,
      "name": "Void_Grass"
    },
    {
      "x": -5,
      "y": 4,
      "z": -15,
      "name": "Void_Grass"
    },
    {
      "x": -5,
      "y": 5,
      "z": -15,
      "name": "Rock_Magma_Cooled"
    },
    {
      "x": -5,
      "y": 6,
      "z": -15,
      "name": "Void_Grass"
    },
    {
      "x": -5,
      "y": 7,
      "z": -15,
      "name": "Rock_Magma_Cooled"
    },
    {
      "x": -5,
      "y": 8,
      "z": -15,
      "name": "Void_Grass"
    },
    {
      "x": -5,
      "y": 4,
      "z": -14,
      "name": "Rock_Magma_Cooled"
    },
    {
      "x": -5,
      "y": 5,
      "z": -14,
      "name": "Void_Grass"
    },
    {
      "x": -5,
      "y": 6,
      "z": -14,
      "name": "Rock_Magma_Cooled"
    },
    {
      "x": -5,
      "y": 7,
      "z": -14,
      "name": "Void_Grass"
    },
    {
      "x": -5,
      "y": 8,
      "z": -14,
      "name": "Void_Grass"
    },
    {
      "x": -5,
      "y": 4,
      "z": -13,
      "name": "Rock_Magma_Cooled"
    },
    {
      "x": -5,
      "y": 5,
      "z": -13,
      "name": "Void_Grass"
    },
    {
      "x": -5,
      "y": 6,
      "z": -13,
      "name": "Void_Grass"
    },
    {
      "x": -5,
      "y": 7,
      "z": -13,
      "name": "Rock_Magma_Cooled"
    },
    {
      "x": -5,
      "y": 8,
      "z": -13,
      "name": "Void_Grass"
    },
    {
      "x": -5,
      "y": 9,
      "z": -13,
      "name": "Rock_Magma_Cooled"
    },
    {
      "x": -5,
      "y": 4,
      "z": -12,
      "name": "Wood_Amber_Roots"
    },
    {
      "x": -5,
      "y": 5,
      "z": -12,
      "name": "Rock_Magma_Cooled"
    },
    {
      "x": -5,
      "y": 6,
      "z": -12,
      "name": "Void_Grass"
    },
    {
      "x": -5,
      "y": 7,
      "z": -12,
      "name": "Void_Grass"
    },
    {
      "x": -5,
      "y": 8,
      "z": -12,
      "name": "Rock_Magma_Cooled"
    },
    {
      "x": -5,
      "y": 9,
      "z": -12,
      "name": "Void_Grass"
    },
    {
      "x": -5,
      "y": 5,
      "z": -11,
      "name": "Wood_Amber_Roots"
    },
    {
      "x": -5,
      "y": 6,
      "z": -11,
      "name": "Void_Grass"
    },
    {
      "x": -5,
      "y": 7,
      "z": -11,
      "name": "Rock_Magma_Cooled"
    },
    {
      "x": -5,
      "y": 8,
      "z": -11,
      "name": "Rock_Magma_Cooled"
    },
    {
      "x": -5,
      "y": 9,
      "z": -11,
      "name": "Void_Grass"
    },
    {
      "x": -5,
      "y": 10,
      "z": -11,
      "name": "Rock_Magma_Cooled"
    },
    {
      "x": -5,
      "y": 7,
      "z": -10,
      "name": "Rock_Magma_Cooled"
    },
    {
      "x": -5,
      "y": 8,
      "z": -10,
      "name": "Rock_Magma_Cooled"
    },
    {
      "x": -5,
      "y": 9,
      "z": -10,
      "name": "Rock_Magma_Cooled"
    },
    {
      "x": -5,
      "y": 10,
      "z": -10,
      "name": "Void_Grass"
    },
    {
      "x": -5,
      "y": 7,
      "z": -9,
      "name": "Rock_Magma_Cooled"
    },
    {
      "x": -5,
      "y": 8,
      "z": -9,
      "name": "Rock_Magma_Cooled"
    },
    {
      "x": -5,
      "y": 9,
      "z": -9,
      "name": "Rock_Magma_Cooled"
    },
    {
      "x": -5,
      "y": 10,
      "z": -9,
      "name": "Rock_Magma_Cooled"
    },
    {
      "x": -5,
      "y": 11,
      "z": -9,
      "name": "Rock_Magma_Cooled"
    },
    {
      "x": -5,
      "y": 7,
      "z": -8,
      "name": "Wood_Azure_Roots"
    },
    {
      "x": -5,
      "y": 8,
      "z": -8,
      "name": "Rock_Magma_Cooled"
    },
    {
      "x": -5,
      "y": 9,
      "z": -8,
      "name": "Rock_Magma_Cooled"
    },
    {
      "x": -5,
      "y": 10,
      "z": -8,
      "name": "Void_Grass"
    },
    {
      "x": -5,
      "y": 11,
      "z": -8,
      "name": "Void_Grass"
    },
    {
      "x": -5,
      "y": 12,
      "z": -8,
      "name": "Void_Grass"
    },
    {
      "x": -5,
      "y": 11,
      "z": -7,
      "name": "Rock_Magma_Cooled"
    },
    {
      "x": -5,
      "y": 12,
      "z": -7,
      "name": "Void_Grass"
    },
    {
      "x": -5,
      "y": 13,
      "z": -7,
      "name": "Rock_Magma_Cooled"
    },
    {
      "x": -5,
      "y": 11,
      "z": -6,
      "name": "Rock_Magma_Cooled"
    },
    {
      "x": -5,
      "y": 12,
      "z": -6,
      "name": "Void_Grass"
    },
    {
      "x": -5,
      "y": 13,
      "z": -6,
      "name": "Void_Grass"
    },
    {
      "x": -5,
      "y": 12,
      "z": -5,
      "name": "Void_Grass"
    },
    {
      "x": -5,
      "y": 13,
      "z": -5,
      "name": "Void_Grass"
    },
    {
      "x": -5,
      "y": 12,
      "z": -4,
      "name": "Rock_Magma_Cooled"
    },
    {
      "x": -5,
      "y": 13,
      "z": -4,
      "name": "Void_Grass"
    },
    {
      "x": -5,
      "y": 13,
      "z": -3,
      "name": "Rock_Magma_Cooled"
    },
    {
      "x": -5,
      "y": 14,
      "z": -3,
      "name": "Void_Grass"
    },
    {
      "x": -5,
      "y": 14,
      "z": -2,
      "name": "Void_Grass"
    },
    {
      "x": -5,
      "y": 14,
      "z": -1,
      "name": "Void_Grass"
    },
    {
      "x": -4,
      "y": 5,
      "z": -17,
      "name": "Void_Grass"
    },
    {
      "x": -4,
      "y": 6,
      "z": -17,
      "name": "Rock_Magma_Cooled"
    },
    {
      "x": -4,
      "y": 4,
      "z": -16,
      "name": "Void_Grass"
    },
    {
      "x": -4,
      "y": 5,
      "z": -16,
      "name": "Void_Grass"
    },
    {
      "x": -4,
      "y": 6,
      "z": -16,
      "name": "Rock_Magma_Cooled"
    },
    {
      "x": -4,
      "y": 7,
      "z": -16,
      "name": "Rock_Magma_Cooled"
    },
    {
      "x": -4,
      "y": 4,
      "z": -15,
      "name": "Void_Grass"
    },
    {
      "x": -4,
      "y": 5,
      "z": -15,
      "name": "Rock_Magma_Cooled"
    },
    {
      "x": -4,
      "y": 6,
      "z": -15,
      "name": "Rock_Magma_Cooled"
    },
    {
      "x": -4,
      "y": 7,
      "z": -15,
      "name": "Rock_Magma_Cooled"
    },
    {
      "x": -4,
      "y": 8,
      "z": -15,
      "name": "Void_Grass"
    },
    {
      "x": -4,
      "y": 4,
      "z": -14,
      "name": "Void_Grass"
    },
    {
      "x": -4,
      "y": 5,
      "z": -14,
      "name": "Rock_Magma_Cooled"
    },
    {
      "x": -4,
      "y": 6,
      "z": -14,
      "name": "Void_Grass"
    },
    {
      "x": -4,
      "y": 7,
      "z": -14,
      "name": "Rock_Magma_Cooled"
    },
    {
      "x": -4,
      "y": 8,
      "z": -14,
      "name": "Void_Grass"
    },
    {
      "x": -4,
      "y": 5,
      "z": -13,
      "name": "Rock_Magma_Cooled"
    },
    {
      "x": -4,
      "y": 6,
      "z": -13,
      "name": "Void_Grass"
    },
    {
      "x": -4,
      "y": 7,
      "z": -13,
      "name": "Rock_Magma_Cooled"
    },
    {
      "x": -4,
      "y": 8,
      "z": -13,
      "name": "Rock_Magma_Cooled"
    },
    {
      "x": -4,
      "y": 9,
      "z": -13,
      "name": "Rock_Magma_Cooled"
    },
    {
      "x": -4,
      "y": 4,
      "z": -12,
      "name": "Wood_Azure_Roots"
    },
    {
      "x": -4,
      "y": 5,
      "z": -12,
      "name": "Rock_Magma_Cooled"
    },
    {
      "x": -4,
      "y": 6,
      "z": -12,
      "name": "Void_Grass"
    },
    {
      "x": -4,
      "y": 7,
      "z": -12,
      "name": "Rock_Magma_Cooled"
    },
    {
      "x": -4,
      "y": 8,
      "z": -12,
      "name": "Void_Grass"
    },
    {
      "x": -4,
      "y": 9,
      "z": -12,
      "name": "Rock_Magma_Cooled"
    },
    {
      "x": -4,
      "y": 10,
      "z": -12,
      "name": "Void_Grass"
    },
    {
      "x": -4,
      "y": 6,
      "z": -11,
      "name": "Void_Grass"
    },
    {
      "x": -4,
      "y": 7,
      "z": -11,
      "name": "Void_Grass"
    },
    {
      "x": -4,
      "y": 8,
      "z": -11,
      "name": "Void_Grass"
    },
    {
      "x": -4,
      "y": 9,
      "z": -11,
      "name": "Void_Grass"
    },
    {
      "x": -4,
      "y": 10,
      "z": -11,
      "name": "Void_Grass"
    },
    {
      "x": -4,
      "y": 7,
      "z": -10,
      "name": "Rock_Magma_Cooled"
    },
    {
      "x": -4,
      "y": 8,
      "z": -10,
      "name": "Void_Grass"
    },
    {
      "x": -4,
      "y": 9,
      "z": -10,
      "name": "Void_Grass"
    },
    {
      "x": -4,
      "y": 10,
      "z": -10,
      "name": "Void_Grass"
    },
    {
      "x": -4,
      "y": 11,
      "z": -10,
      "name": "Rock_Magma_Cooled"
    },
    {
      "x": -4,
      "y": 7,
      "z": -9,
      "name": "Rock_Magma_Cooled"
    },
    {
      "x": -4,
      "y": 8,
      "z": -9,
      "name": "Rock_Magma_Cooled"
    },
    {
      "x": -4,
      "y": 9,
      "z": -9,
      "name": "Void_Grass"
    },
    {
      "x": -4,
      "y": 10,
      "z": -9,
      "name": "Rock_Magma_Cooled"
    },
    {
      "x": -4,
      "y": 11,
      "z": -9,
      "name": "Void_Grass"
    },
    {
      "x": -4,
      "y": 12,
      "z": -9,
      "name": "Void_Grass"
    },
    {
      "x": -4,
      "y": 8,
      "z": -8,
      "name": "Void_Grass"
    },
    {
      "x": -4,
      "y": 9,
      "z": -8,
      "name": "Void_Grass"
    },
    {
      "x": -4,
      "y": 10,
      "z": -8,
      "name": "Void_Grass"
    },
    {
      "x": -4,
      "y": 11,
      "z": -8,
      "name": "Void_Grass"
    },
    {
      "x": -4,
      "y": 12,
      "z": -8,
      "name": "Rock_Magma_Cooled"
    },
    {
      "x": -4,
      "y": 13,
      "z": -8,
      "name": "Void_Grass"
    },
    {
      "x": -4,
      "y": 8,
      "z": -7,
      "name": "Wood_Amber_Roots"
    },
    {
      "x": -4,
      "y": 9,
      "z": -7,
      "name": "Rock_Magma_Cooled"
    },
    {
      "x": -4,
      "y": 10,
      "z": -7,
      "name": "Void_Grass"
    },
    {
      "x": -4,
      "y": 11,
      "z": -7,
      "name": "Rock_Magma_Cooled"
    },
    {
      "x": -4,
      "y": 12,
      "z": -7,
      "name": "Void_Grass"
    },
    {
      "x": -4,
      "y": 13,
      "z": -7,
      "name": "Rock_Magma_Cooled"
    },
    {
      "x": -4,
      "y": 11,
      "z": -6,
      "name": "Rock_Crystal_Purple_Block"
    },
    {
      "x": -4,
      "y": 12,
      "z": -6,
      "name": "Rock_Magma_Cooled"
    },
    {
      "x": -4,
      "y": 13,
      "z": -6,
      "name": "Void_Grass"
    },
    {
      "x": -4,
      "y": 11,
      "z": -5,
      "name": "Void_Grass"
    },
    {
      "x": -4,
      "y": 12,
      "z": -5,
      "name": "Void_Grass"
    },
    {
      "x": -4,
      "y": 13,
      "z": -5,
      "name": "Void_Grass"
    },
    {
      "x": -4,
      "y": 14,
      "z": -5,
      "name": "Void_Grass"
    },
    {
      "x": -4,
      "y": 10,
      "z": -4,
      "name": "Wood_Amber_Roots"
    },
    {
      "x": -4,
      "y": 11,
      "z": -4,
      "name": "Rock_Magma_Cooled"
    },
    {
      "x": -4,
      "y": 12,
      "z": -4,
      "name": "Rock_Magma_Cooled"
    },
    {
      "x": -4,
      "y": 13,
      "z": -4,
      "name": "Rock_Magma_Cooled"
    },
    {
      "x": -4,
      "y": 14,
      "z": -4,
      "name": "Rock_Magma_Cooled"
    },
    {
      "x": -4,
      "y": 11,
      "z": -3,
      "name": "Wood_Amber_Roots"
    },
    {
      "x": -4,
      "y": 12,
      "z": -3,
      "name": "Rock_Magma_Cooled"
    },
    {
      "x": -4,
      "y": 13,
      "z": -3,
      "name": "Void_Grass"
    },
    {
      "x": -4,
      "y": 14,
      "z": -3,
      "name": "Void_Grass"
    },
    {
      "x": -4,
      "y": 15,
      "z": -3,
      "name": "Rock_Magma_Cooled"
    },
    {
      "x": -4,
      "y": 13,
      "z": -2,
      "name": "Void_Grass"
    },
    {
      "x": -4,
      "y": 14,
      "z": -2,
      "name": "Void_Grass"
    },
    {
      "x": -4,
      "y": 15,
      "z": -2,
      "name": "Void_Grass"
    },
    {
      "x": -4,
      "y": 13,
      "z": -1,
      "name": "Void_Grass"
    },
    {
      "x": -4,
      "y": 14,
      "z": -1,
      "name": "Rock_Magma_Cooled"
    },
    {
      "x": -4,
      "y": 15,
      "z": -1,
      "name": "Rock_Magma_Cooled"
    },
    {
      "x": -4,
      "y": 14,
      "z": 0,
      "name": "Rock_Magma_Cooled"
    },
    {
      "x": -4,
      "y": 15,
      "z": 0,
      "name": "Rock_Magma_Cooled"
    },
    {
      "x": -4,
      "y": 15,
      "z": 1,
      "name": "Void_Grass"
    },
    {
      "x": -4,
      "y": 16,
      "z": 1,
      "name": "Void_Grass"
    },
    {
      "x": -4,
      "y": 16,
      "z": 2,
      "name": "Rock_Magma_Cooled"
    },
    {
      "x": -4,
      "y": 16,
      "z": 3,
      "name": "Void_Grass"
    },
    {
      "x": -3,
      "y": 5,
      "z": -16,
      "name": "Rock_Magma_Cooled"
    },
    {
      "x": -3,
      "y": 6,
      "z": -16,
      "name": "Void_Grass"
    },
    {
      "x": -3,
      "y": 5,
      "z": -15,
      "name": "Void_Grass"
    },
    {
      "x": -3,
      "y": 6,
      "z": -15,
      "name": "Void_Grass"
    },
    {
      "x": -3,
      "y": 7,
      "z": -15,
      "name": "Void_Grass"
    },
    {
      "x": -3,
      "y": 5,
      "z": -14,
      "name": "Rock_Magma_Cooled"
    },
    {
      "x": -3,
      "y": 6,
      "z": -14,
      "name": "Rock_Magma_Cooled"
    },
    {
      "x": -3,
      "y": 7,
      "z": -14,
      "name": "Void_Grass"
    },
    {
      "x": -3,
      "y": 8,
      "z": -14,
      "name": "Void_Grass"
    },
    {
      "x": -3,
      "y": 5,
      "z": -13,
      "name": "Rock_Magma_Cooled"
    },
    {
      "x": -3,
      "y": 6,
      "z": -13,
      "name": "Rock_Magma_Cooled"
    },
    {
      "x": -3,
      "y": 7,
      "z": -13,
      "name": "Rock_Magma_Cooled"
    },
    {
      "x": -3,
      "y": 8,
      "z": -13,
      "name": "Rock_Magma_Cooled"
    },
    {
      "x": -3,
      "y": 9,
      "z": -13,
      "name": "Void_Grass"
    },
    {
      "x": -3,
      "y": 6,
      "z": -12,
      "name": "Rock_Magma_Cooled"
    },
    {
      "x": -3,
      "y": 7,
      "z": -12,
      "name": "Rock_Magma_Cooled"
    },
    {
      "x": -3,
      "y": 8,
      "z": -12,
      "name": "Rock_Magma_Cooled"
    },
    {
      "x": -3,
      "y": 9,
      "z": -12,
      "name": "Void_Grass"
    },
    {
      "x": -3,
      "y": 10,
      "z": -12,
      "name": "Void_Grass"
    },
    {
      "x": -3,
      "y": 7,
      "z": -11,
      "name": "Void_Grass"
    },
    {
      "x": -3,
      "y": 8,
      "z": -11,
      "name": "Void_Grass"
    },
    {
      "x": -3,
      "y": 9,
      "z": -11,
      "name": "Void_Grass"
    },
    {
      "x": -3,
      "y": 10,
      "z": -11,
      "name": "Void_Grass"
    },
    {
      "x": -3,
      "y": 11,
      "z": -11,
      "name": "Void_Grass"
    },
    {
      "x": -3,
      "y": 7,
      "z": -10,
      "name": "Rock_Magma_Cooled"
    },
    {
      "x": -3,
      "y": 8,
      "z": -10,
      "name": "Void_Grass"
    },
    {
      "x": -3,
      "y": 9,
      "z": -10,
      "name": "Void_Grass"
    },
    {
      "x": -3,
      "y": 10,
      "z": -10,
      "name": "Void_Grass"
    },
    {
      "x": -3,
      "y": 11,
      "z": -10,
      "name": "Rock_Magma_Cooled"
    },
    {
      "x": -3,
      "y": 12,
      "z": -10,
      "name": "Rock_Magma_Cooled"
    },
    {
      "x": -3,
      "y": 7,
      "z": -9,
      "name": "Void_Grass"
    },
    {
      "x": -3,
      "y": 8,
      "z": -9,
      "name": "Rock_Magma_Cooled"
    },
    {
      "x": -3,
      "y": 9,
      "z": -9,
      "name": "Void_Grass"
    },
    {
      "x": -3,
      "y": 10,
      "z": -9,
      "name": "Rock_Magma_Cooled"
    },
    {
      "x": -3,
      "y": 11,
      "z": -9,
      "name": "Void_Grass"
    },
    {
      "x": -3,
      "y": 12,
      "z": -9,
      "name": "Rock_Magma_Cooled"
    },
    {
      "x": -3,
      "y": 8,
      "z": -8,
      "name": "Rock_Magma_Cooled"
    },
    {
      "x": -3,
      "y": 9,
      "z": -8,
      "name": "Rock_Magma_Cooled"
    },
    {
      "x": -3,
      "y": 10,
      "z": -8,
      "name": "Void_Grass"
    },
    {
      "x": -3,
      "y": 11,
      "z": -8,
      "name": "Rock_Magma_Cooled"
    },
    {
      "x": -3,
      "y": 12,
      "z": -8,
      "name": "Rock_Magma_Cooled"
    },
    {
      "x": -3,
      "y": 13,
      "z": -8,
      "name": "Void_Grass"
    },
    {
      "x": -3,
      "y": 9,
      "z": -7,
      "name": "Void_Grass"
    },
    {
      "x": -3,
      "y": 10,
      "z": -7,
      "name": "Rock_Magma_Cooled"
    },
    {
      "x": -3,
      "y": 11,
      "z": -7,
      "name": "Void_Grass"
    },
    {
      "x": -3,
      "y": 12,
      "z": -7,
      "name": "Void_Grass"
    },
    {
      "x": -3,
      "y": 13,
      "z": -7,
      "name": "Rock_Magma_Cooled"
    },
    {
      "x": -3,
      "y": 9,
      "z": -6,
      "name": "Wood_Azure_Roots"
    },
    {
      "x": -3,
      "y": 10,
      "z": -6,
      "name": "Rock_Magma_Cooled"
    },
    {
      "x": -3,
      "y": 11,
      "z": -6,
      "name": "Void_Grass"
    },
    {
      "x": -3,
      "y": 12,
      "z": -6,
      "name": "Void_Grass"
    },
    {
      "x": -3,
      "y": 13,
      "z": -6,
      "name": "Rock_Magma_Cooled"
    },
    {
      "x": -3,
      "y": 14,
      "z": -6,
      "name": "Void_Grass"
    },
    {
      "x": -3,
      "y": 11,
      "z": -5,
      "name": "Rock_Magma_Cooled"
    },
    {
      "x": -3,
      "y": 12,
      "z": -5,
      "name": "Void_Grass"
    },
    {
      "x": -3,
      "y": 13,
      "z": -5,
      "name": "Rock_Magma_Cooled"
    },
    {
      "x": -3,
      "y": 14,
      "z": -5,
      "name": "Rock_Magma_Cooled"
    },
    {
      "x": -3,
      "y": 10,
      "z": -4,
      "name": "Wood_Amber_Roots"
    },
    {
      "x": -3,
      "y": 11,
      "z": -4,
      "name": "Void_Grass"
    },
    {
      "x": -3,
      "y": 12,
      "z": -4,
      "name": "Rock_Magma_Cooled"
    },
    {
      "x": -3,
      "y": 13,
      "z": -4,
      "name": "Rock_Magma_Cooled"
    },
    {
      "x": -3,
      "y": 14,
      "z": -4,
      "name": "Rock_Magma_Cooled"
    },
    {
      "x": -3,
      "y": 15,
      "z": -4,
      "name": "Void_Grass"
    },
    {
      "x": -3,
      "y": 12,
      "z": -3,
      "name": "Void_Grass"
    },
    {
      "x": -3,
      "y": 13,
      "z": -3,
      "name": "Rock_Magma_Cooled"
    },
    {
      "x": -3,
      "y": 14,
      "z": -3,
      "name": "Void_Grass"
    },
    {
      "x": -3,
      "y": 15,
      "z": -3,
      "name": "Void_Grass"
    },
    {
      "x": -3,
      "y": 11,
      "z": -2,
      "name": "Wood_Amber_Roots"
    },
    {
      "x": -3,
      "y": 12,
      "z": -2,
      "name": "Void_Grass"
    },
    {
      "x": -3,
      "y": 13,
      "z": -2,
      "name": "Void_Grass"
    },
    {
      "x": -3,
      "y": 14,
      "z": -2,
      "name": "Void_Grass"
    },
    {
      "x": -3,
      "y": 15,
      "z": -2,
      "name": "Void_Grass"
    },
    {
      "x": -3,
      "y": 13,
      "z": -1,
      "name": "Rock_Magma_Cooled"
    },
    {
      "x": -3,
      "y": 14,
      "z": -1,
      "name": "Rock_Magma_Cooled"
    },
    {
      "x": -3,
      "y": 15,
      "z": -1,
      "name": "Rock_Magma_Cooled"
    },
    {
      "x": -3,
      "y": 16,
      "z": -1,
      "name": "Void_Grass"
    },
    {
      "x": -3,
      "y": 13,
      "z": 0,
      "name": "Rock_Magma_Cooled"
    },
    {
      "x": -3,
      "y": 14,
      "z": 0,
      "name": "Void_Grass"
    },
    {
      "x": -3,
      "y": 15,
      "z": 0,
      "name": "Void_Grass"
    },
    {
      "x": -3,
      "y": 16,
      "z": 0,
      "name": "Rock_Magma_Cooled"
    },
    {
      "x": -3,
      "y": 13,
      "z": 1,
      "name": "Wood_Azure_Roots"
    },
    {
      "x": -3,
      "y": 14,
      "z": 1,
      "name": "Void_Grass"
    },
    {
      "x": -3,
      "y": 15,
      "z": 1,
      "name": "Rock_Magma_Cooled"
    },
    {
      "x": -3,
      "y": 16,
      "z": 1,
      "name": "Void_Grass"
    },
    {
      "x": -3,
      "y": 17,
      "z": 1,
      "name": "Void_Grass"
    },
    {
      "x": -3,
      "y": 15,
      "z": 2,
      "name": "Rock_Magma_Cooled"
    },
    {
      "x": -3,
      "y": 16,
      "z": 2,
      "name": "Void_Grass"
    },
    {
      "x": -3,
      "y": 17,
      "z": 2,
      "name": "Void_Grass"
    },
    {
      "x": -3,
      "y": 15,
      "z": 3,
      "name": "Rock_Magma_Cooled"
    },
    {
      "x": -3,
      "y": 16,
      "z": 3,
      "name": "Rock_Magma_Cooled"
    },
    {
      "x": -3,
      "y": 17,
      "z": 3,
      "name": "Rock_Magma_Cooled"
    },
    {
      "x": -3,
      "y": 15,
      "z": 4,
      "name": "Void_Grass"
    },
    {
      "x": -3,
      "y": 16,
      "z": 4,
      "name": "Rock_Magma_Cooled"
    },
    {
      "x": -3,
      "y": 17,
      "z": 4,
      "name": "Void_Grass"
    },
    {
      "x": -3,
      "y": 17,
      "z": 5,
      "name": "Void_Grass"
    },
    {
      "x": -2,
      "y": 6,
      "z": -15,
      "name": "Rock_Magma_Cooled"
    },
    {
      "x": -2,
      "y": 6,
      "z": -14,
      "name": "Void_Grass"
    },
    {
      "x": -2,
      "y": 7,
      "z": -14,
      "name": "Rock_Magma_Cooled"
    },
    {
      "x": -2,
      "y": 6,
      "z": -13,
      "name": "Void_Grass"
    },
    {
      "x": -2,
      "y": 7,
      "z": -13,
      "name": "Void_Grass"
    },
    {
      "x": -2,
      "y": 8,
      "z": -13,
      "name": "Rock_Magma_Cooled"
    },
    {
      "x": -2,
      "y": 9,
      "z": -13,
      "name": "Void_Grass"
    },
    {
      "x": -2,
      "y": 7,
      "z": -12,
      "name": "Rock_Magma_Cooled"
    },
    {
      "x": -2,
      "y": 8,
      "z": -12,
      "name": "Void_Grass"
    },
    {
      "x": -2,
      "y": 9,
      "z": -12,
      "name": "Rock_Magma_Cooled"
    },
    {
      "x": -2,
      "y": 10,
      "z": -12,
      "name": "Void_Grass"
    },
    {
      "x": -2,
      "y": 7,
      "z": -11,
      "name": "Rock_Magma_Cooled"
    },
    {
      "x": -2,
      "y": 8,
      "z": -11,
      "name": "Void_Grass"
    },
    {
      "x": -2,
      "y": 9,
      "z": -11,
      "name": "Rock_Magma_Cooled"
    },
    {
      "x": -2,
      "y": 10,
      "z": -11,
      "name": "Void_Grass"
    },
    {
      "x": -2,
      "y": 11,
      "z": -11,
      "name": "Rock_Magma_Cooled"
    },
    {
      "x": -2,
      "y": 7,
      "z": -10,
      "name": "Rock_Crystal_Purple_Block",
      "rotation": 4
    },
    {
      "x": -2,
      "y": 8,
      "z": -10,
      "name": "Void_Grass"
    },
    {
      "x": -2,
      "y": 9,
      "z": -10,
      "name": "Void_Grass"
    },
    {
      "x": -2,
      "y": 10,
      "z": -10,
      "name": "Rock_Magma_Cooled"
    },
    {
      "x": -2,
      "y": 11,
      "z": -10,
      "name": "Rock_Magma_Cooled"
    },
    {
      "x": -2,
      "y": 12,
      "z": -10,
      "name": "Void_Grass"
    },
    {
      "x": -2,
      "y": 8,
      "z": -9,
      "name": "Rock_Magma_Cooled"
    },
    {
      "x": -2,
      "y": 9,
      "z": -9,
      "name": "Rock_Magma_Cooled"
    },
    {
      "x": -2,
      "y": 10,
      "z": -9,
      "name": "Rock_Magma_Cooled"
    },
    {
      "x": -2,
      "y": 11,
      "z": -9,
      "name": "Void_Grass"
    },
    {
      "x": -2,
      "y": 12,
      "z": -9,
      "name": "Rock_Magma_Cooled"
    },
    {
      "x": -2,
      "y": 7,
      "z": -8,
      "name": "Wood_Azure_Roots"
    },
    {
      "x": -2,
      "y": 8,
      "z": -8,
      "name": "Rock_Magma_Cooled"
    },
    {
      "x": -2,
      "y": 9,
      "z": -8,
      "name": "Void_Grass"
    },
    {
      "x": -2,
      "y": 10,
      "z": -8,
      "name": "Rock_Magma_Cooled"
    },
    {
      "x": -2,
      "y": 11,
      "z": -8,
      "name": "Void_Grass"
    },
    {
      "x": -2,
      "y": 12,
      "z": -8,
      "name": "Void_Grass"
    },
    {
      "x": -2,
      "y": 13,
      "z": -8,
      "name": "Void_Grass"
    },
    {
      "x": -2,
      "y": 9,
      "z": -7,
      "name": "Rock_Magma_Cooled"
    },
    {
      "x": -2,
      "y": 10,
      "z": -7,
      "name": "Void_Grass"
    },
    {
      "x": -2,
      "y": 11,
      "z": -7,
      "name": "Rock_Magma_Cooled"
    },
    {
      "x": -2,
      "y": 12,
      "z": -7,
      "name": "Rock_Magma_Cooled"
    },
    {
      "x": -2,
      "y": 13,
      "z": -7,
      "name": "Rock_Magma_Cooled"
    },
    {
      "x": -2,
      "y": 9,
      "z": -6,
      "name": "Wood_Azure_Roots"
    },
    {
      "x": -2,
      "y": 10,
      "z": -6,
      "name": "Void_Grass"
    },
    {
      "x": -2,
      "y": 11,
      "z": -6,
      "name": "Void_Grass"
    },
    {
      "x": -2,
      "y": 12,
      "z": -6,
      "name": "Void_Grass"
    },
    {
      "x": -2,
      "y": 13,
      "z": -6,
      "name": "Rock_Magma_Cooled"
    },
    {
      "x": -2,
      "y": 14,
      "z": -6,
      "name": "Void_Grass"
    },
    {
      "x": -2,
      "y": 10,
      "z": -5,
      "name": "Wood_Azure_Roots"
    },
    {
      "x": -2,
      "y": 11,
      "z": -5,
      "name": "Void_Grass"
    },
    {
      "x": -2,
      "y": 12,
      "z": -5,
      "name": "Void_Grass"
    },
    {
      "x": -2,
      "y": 13,
      "z": -5,
      "name": "Void_Grass"
    },
    {
      "x": -2,
      "y": 14,
      "z": -5,
      "name": "Rock_Magma_Cooled"
    },
    {
      "x": -2,
      "y": 11,
      "z": -4,
      "name": "Rock_Magma_Cooled"
    },
    {
      "x": -2,
      "y": 12,
      "z": -4,
      "name": "Rock_Magma_Cooled"
    },
    {
      "x": -2,
      "y": 13,
      "z": -4,
      "name": "Void_Grass"
    },
    {
      "x": -2,
      "y": 14,
      "z": -4,
      "name": "Rock_Magma_Cooled"
    },
    {
      "x": -2,
      "y": 15,
      "z": -4,
      "name": "Void_Grass"
    },
    {
      "x": -2,
      "y": 11,
      "z": -3,
      "name": "Wood_Azure_Roots"
    },
    {
      "x": -2,
      "y": 12,
      "z": -3,
      "name": "Rock_Magma_Cooled"
    },
    {
      "x": -2,
      "y": 13,
      "z": -3,
      "name": "Void_Grass"
    },
    {
      "x": -2,
      "y": 14,
      "z": -3,
      "name": "Void_Grass"
    },
    {
      "x": -2,
      "y": 15,
      "z": -3,
      "name": "Void_Grass"
    },
    {
      "x": -2,
      "y": 12,
      "z": -2,
      "name": "Rock_Magma_Cooled"
    },
    {
      "x": -2,
      "y": 13,
      "z": -2,
      "name": "Void_Grass"
    },
    {
      "x": -2,
      "y": 14,
      "z": -2,
      "name": "Rock_Magma_Cooled"
    },
    {
      "x": -2,
      "y": 15,
      "z": -2,
      "name": "Rock_Magma_Cooled"
    },
    {
      "x": -2,
      "y": 16,
      "z": -2,
      "name": "Rock_Magma_Cooled"
    },
    {
      "x": -2,
      "y": 12,
      "z": -1,
      "name": "Wood_Amber_Roots"
    },
    {
      "x": -2,
      "y": 13,
      "z": -1,
      "name": "Rock_Magma_Cooled"
    },
    {
      "x": -2,
      "y": 14,
      "z": -1,
      "name": "Rock_Magma_Cooled"
    },
    {
      "x": -2,
      "y": 15,
      "z": -1,
      "name": "Rock_Magma_Cooled"
    },
    {
      "x": -2,
      "y": 16,
      "z": -1,
      "name": "Void_Grass"
    },
    {
      "x": -2,
      "y": 12,
      "z": 0,
      "name": "Wood_Amber_Roots"
    },
    {
      "x": -2,
      "y": 13,
      "z": 0,
      "name": "Rock_Magma_Cooled"
    },
    {
      "x": -2,
      "y": 14,
      "z": 0,
      "name": "Rock_Magma_Cooled"
    },
    {
      "x": -2,
      "y": 15,
      "z": 0,
      "name": "Rock_Magma_Cooled"
    },
    {
      "x": -2,
      "y": 16,
      "z": 0,
      "name": "Void_Grass"
    },
    {
      "x": -2,
      "y": 14,
      "z": 1,
      "name": "Rock_Magma_Cooled"
    },
    {
      "x": -2,
      "y": 15,
      "z": 1,
      "name": "Void_Grass"
    },
    {
      "x": -2,
      "y": 16,
      "z": 1,
      "name": "Rock_Magma_Cooled"
    },
    {
      "x": -2,
      "y": 17,
      "z": 1,
      "name": "Rock_Magma_Cooled"
    },
    {
      "x": -2,
      "y": 14,
      "z": 2,
      "name": "Void_Grass"
    },
    {
      "x": -2,
      "y": 15,
      "z": 2,
      "name": "Rock_Magma_Cooled"
    },
    {
      "x": -2,
      "y": 16,
      "z": 2,
      "name": "Rock_Magma_Cooled"
    },
    {
      "x": -2,
      "y": 17,
      "z": 2,
      "name": "Void_Grass"
    },
    {
      "x": -2,
      "y": 14,
      "z": 3,
      "name": "Rock_Magma_Cooled"
    },
    {
      "x": -2,
      "y": 15,
      "z": 3,
      "name": "Void_Grass"
    },
    {
      "x": -2,
      "y": 16,
      "z": 3,
      "name": "Void_Grass"
    },
    {
      "x": -2,
      "y": 17,
      "z": 3,
      "name": "Rock_Magma_Cooled"
    },
    {
      "x": -2,
      "y": 18,
      "z": 3,
      "name": "Void_Grass"
    },
    {
      "x": -2,
      "y": 14,
      "z": 4,
      "name": "Void_Grass"
    },
    {
      "x": -2,
      "y": 15,
      "z": 4,
      "name": "Void_Grass"
    },
    {
      "x": -2,
      "y": 16,
      "z": 4,
      "name": "Rock_Magma_Cooled"
    },
    {
      "x": -2,
      "y": 17,
      "z": 4,
      "name": "Void_Grass"
    },
    {
      "x": -2,
      "y": 18,
      "z": 4,
      "name": "Void_Grass"
    },
    {
      "x": -2,
      "y": 15,
      "z": 5,
      "name": "Rock_Magma_Cooled"
    },
    {
      "x": -2,
      "y": 16,
      "z": 5,
      "name": "Void_Grass"
    },
    {
      "x": -2,
      "y": 17,
      "z": 5,
      "name": "Rock_Magma_Cooled"
    },
    {
      "x": -2,
      "y": 18,
      "z": 5,
      "name": "Void_Grass"
    },
    {
      "x": -2,
      "y": 16,
      "z": 6,
      "name": "Void_Grass"
    },
    {
      "x": -2,
      "y": 17,
      "z": 6,
      "name": "Void_Grass"
    },
    {
      "x": -1,
      "y": 8,
      "z": -12,
      "name": "Void_Grass"
    },
    {
      "x": -1,
      "y": 9,
      "z": -12,
      "name": "Rock_Magma_Cooled"
    },
    {
      "x": -1,
      "y": 10,
      "z": -12,
      "name": "Void_Grass"
    },
    {
      "x": -1,
      "y": 7,
      "z": -11,
      "name": "Wood_Amber_Roots"
    },
    {
      "x": -1,
      "y": 8,
      "z": -11,
      "name": "Rock_Magma_Cooled"
    },
    {
      "x": -1,
      "y": 9,
      "z": -11,
      "name": "Rock_Magma_Cooled"
    },
    {
      "x": -1,
      "y": 10,
      "z": -11,
      "name": "Void_Grass"
    },
    {
      "x": -1,
      "y": 11,
      "z": -11,
      "name": "Rock_Magma_Cooled"
    },
    {
      "x": -1,
      "y": 8,
      "z": -10,
      "name": "Rock_Magma_Cooled"
    },
    {
      "x": -1,
      "y": 9,
      "z": -10,
      "name": "Rock_Magma_Cooled"
    },
    {
      "x": -1,
      "y": 10,
      "z": -10,
      "name": "Rock_Magma_Cooled"
    },
    {
      "x": -1,
      "y": 11,
      "z": -10,
      "name": "Void_Grass"
    },
    {
      "x": -1,
      "y": 12,
      "z": -10,
      "name": "Void_Grass"
    },
    {
      "x": -1,
      "y": 7,
      "z": -9,
      "name": "Wood_Amber_Roots"
    },
    {
      "x": -1,
      "y": 8,
      "z": -9,
      "name": "Void_Grass"
    },
    {
      "x": -1,
      "y": 9,
      "z": -9,
      "name": "Void_Grass"
    },
    {
      "x": -1,
      "y": 10,
      "z": -9,
      "name": "Void_Grass"
    },
    {
      "x": -1,
      "y": 11,
      "z": -9,
      "name": "Void_Grass"
    },
    {
      "x": -1,
      "y": 12,
      "z": -9,
      "name": "Void_Grass"
    },
    {
      "x": -1,
      "y": 9,
      "z": -8,
      "name": "Rock_Magma_Cooled"
    },
    {
      "x": -1,
      "y": 10,
      "z": -8,
      "name": "Void_Grass"
    },
    {
      "x": -1,
      "y": 11,
      "z": -8,
      "name": "Rock_Magma_Cooled"
    },
    {
      "x": -1,
      "y": 12,
      "z": -8,
      "name": "Rock_Magma_Cooled"
    },
    {
      "x": -1,
      "y": 9,
      "z": -7,
      "name": "Void_Grass"
    },
    {
      "x": -1,
      "y": 10,
      "z": -7,
      "name": "Void_Grass"
    },
    {
      "x": -1,
      "y": 11,
      "z": -7,
      "name": "Rock_Magma_Cooled"
    },
    {
      "x": -1,
      "y": 12,
      "z": -7,
      "name": "Void_Grass"
    },
    {
      "x": -1,
      "y": 13,
      "z": -7,
      "name": "Void_Grass"
    },
    {
      "x": -1,
      "y": 9,
      "z": -6,
      "name": "Wood_Azure_Roots"
    },
    {
      "x": -1,
      "y": 10,
      "z": -6,
      "name": "Void_Grass"
    },
    {
      "x": -1,
      "y": 11,
      "z": -6,
      "name": "Void_Grass"
    },
    {
      "x": -1,
      "y": 12,
      "z": -6,
      "name": "Rock_Magma_Cooled"
    },
    {
      "x": -1,
      "y": 13,
      "z": -6,
      "name": "Void_Grass"
    },
    {
      "x": -1,
      "y": 14,
      "z": -6,
      "name": "Rock_Magma_Cooled"
    },
    {
      "x": -1,
      "y": 11,
      "z": -5,
      "name": "Void_Grass"
    },
    {
      "x": -1,
      "y": 12,
      "z": -5,
      "name": "Rock_Magma_Cooled"
    },
    {
      "x": -1,
      "y": 13,
      "z": -5,
      "name": "Rock_Magma_Cooled"
    },
    {
      "x": -1,
      "y": 14,
      "z": -5,
      "name": "Void_Grass"
    },
    {
      "x": -1,
      "y": 11,
      "z": -4,
      "name": "Wood_Amber_Roots"
    },
    {
      "x": -1,
      "y": 12,
      "z": -4,
      "name": "Rock_Magma_Cooled"
    },
    {
      "x": -1,
      "y": 13,
      "z": -4,
      "name": "Rock_Magma_Cooled"
    },
    {
      "x": -1,
      "y": 14,
      "z": -4,
      "name": "Void_Grass"
    },
    {
      "x": -1,
      "y": 15,
      "z": -4,
      "name": "Rock_Magma_Cooled"
    },
    {
      "x": -1,
      "y": 12,
      "z": -3,
      "name": "Void_Grass"
    },
    {
      "x": -1,
      "y": 13,
      "z": -3,
      "name": "Void_Grass"
    },
    {
      "x": -1,
      "y": 14,
      "z": -3,
      "name": "Rock_Magma_Cooled"
    },
    {
      "x": -1,
      "y": 15,
      "z": -3,
      "name": "Rock_Magma_Cooled"
    },
    {
      "x": -1,
      "y": 12,
      "z": -2,
      "name": "Void_Grass"
    },
    {
      "x": -1,
      "y": 13,
      "z": -2,
      "name": "Void_Grass"
    },
    {
      "x": -1,
      "y": 14,
      "z": -2,
      "name": "Void_Grass"
    },
    {
      "x": -1,
      "y": 15,
      "z": -2,
      "name": "Void_Grass"
    },
    {
      "x": -1,
      "y": 16,
      "z": -2,
      "name": "Rock_Magma_Cooled"
    },
    {
      "x": -1,
      "y": 13,
      "z": -1,
      "name": "Rock_Magma_Cooled"
    },
    {
      "x": -1,
      "y": 14,
      "z": -1,
      "name": "Rock_Magma_Cooled"
    },
    {
      "x": -1,
      "y": 15,
      "z": -1,
      "name": "Void_Grass"
    },
    {
      "x": -1,
      "y": 16,
      "z": -1,
      "name": "Rock_Magma_Cooled"
    },
    {
      "x": -1,
      "y": 12,
      "z": 0,
      "name": "Wood_Amber_Roots"
    },
    {
      "x": -1,
      "y": 13,
      "z": 0,
      "name": "Void_Grass"
    },
    {
      "x": -1,
      "y": 14,
      "z": 0,
      "name": "Rock_Magma_Cooled"
    },
    {
      "x": -1,
      "y": 15,
      "z": 0,
      "name": "Rock_Magma_Cooled"
    },
    {
      "x": -1,
      "y": 16,
      "z": 0,
      "name": "Rock_Magma_Cooled"
    },
    {
      "x": -1,
      "y": 14,
      "z": 1,
      "name": "Void_Grass"
    },
    {
      "x": -1,
      "y": 15,
      "z": 1,
      "name": "Rock_Magma_Cooled"
    },
    {
      "x": -1,
      "y": 16,
      "z": 1,
      "name": "Void_Grass"
    },
    {
      "x": -1,
      "y": 17,
      "z": 1,
      "name": "Void_Grass"
    },
    {
      "x": -1,
      "y": 13,
      "z": 2,
      "name": "Wood_Amber_Roots"
    },
    {
      "x": -1,
      "y": 14,
      "z": 2,
      "name": "Rock_Magma_Cooled"
    },
    {
      "x": -1,
      "y": 15,
      "z": 2,
      "name": "Void_Grass"
    },
    {
      "x": -1,
      "y": 16,
      "z": 2,
      "name": "Rock_Magma_Cooled"
    },
    {
      "x": -1,
      "y": 17,
      "z": 2,
      "name": "Void_Grass"
    },
    {
      "x": -1,
      "y": 13,
      "z": 3,
      "name": "Wood_Amber_Roots"
    },
    {
      "x": -1,
      "y": 14,
      "z": 3,
      "name": "Rock_Magma_Cooled"
    },
    {
      "x": -1,
      "y": 15,
      "z": 3,
      "name": "Rock_Magma_Cooled"
    },
    {
      "x": -1,
      "y": 16,
      "z": 3,
      "name": "Rock_Magma_Cooled"
    },
    {
      "x": -1,
      "y": 17,
      "z": 3,
      "name": "Void_Grass"
    },
    {
      "x": -1,
      "y": 18,
      "z": 3,
      "name": "Void_Grass"
    },
    {
      "x": -1,
      "y": 13,
      "z": 4,
      "name": "Wood_Amber_Roots"
    },
    {
      "x": -1,
      "y": 14,
      "z": 4,
      "name": "Void_Grass"
    },
    {
      "x": -1,
      "y": 15,
      "z": 4,
      "name": "Rock_Magma_Cooled"
    },
    {
      "x": -1,
      "y": 16,
      "z": 4,
      "name": "Rock_Magma_Cooled"
    },
    {
      "x": -1,
      "y": 17,
      "z": 4,
      "name": "Void_Grass"
    },
    {
      "x": -1,
      "y": 18,
      "z": 4,
      "name": "Void_Grass"
    },
    {
      "x": -1,
      "y": 14,
      "z": 5,
      "name": "Plant_Vine_Wall_Dead",
      "support": 15,
      "rotation": 3
    },
    {
      "x": -1,
      "y": 15,
      "z": 5,
      "name": "Rock_Magma_Cooled"
    },
    {
      "x": -1,
      "y": 16,
      "z": 5,
      "name": "Rock_Magma_Cooled"
    },
    {
      "x": -1,
      "y": 17,
      "z": 5,
      "name": "Rock_Magma_Cooled"
    },
    {
      "x": -1,
      "y": 18,
      "z": 5,
      "name": "Void_Grass"
    },
    {
      "x": -1,
      "y": 15,
      "z": 6,
      "name": "Void_Grass"
    },
    {
      "x": -1,
      "y": 16,
      "z": 6,
      "name": "Void_Grass"
    },
    {
      "x": -1,
      "y": 17,
      "z": 6,
      "name": "Rock_Magma_Cooled"
    },
    {
      "x": -1,
      "y": 15,
      "z": 7,
      "name": "Void_Grass"
    },
    {
      "x": -1,
      "y": 16,
      "z": 7,
      "name": "Rock_Magma_Cooled"
    },
    {
      "x": -1,
      "y": 17,
      "z": 7,
      "name": "Rock_Magma_Cooled"
    },
    {
      "x": -1,
      "y": 15,
      "z": 8,
      "name": "Rock_Magma_Cooled"
    },
    {
      "x": -1,
      "y": 16,
      "z": 8,
      "name": "Void_Grass"
    },
    {
      "x": -1,
      "y": 15,
      "z": 9,
      "name": "Rock_Magma_Cooled"
    },
    {
      "x": -1,
      "y": 16,
      "z": 9,
      "name": "Void_Grass"
    },
    {
      "x": 0,
      "y": 9,
      "z": -11,
      "name": "Rock_Magma_Cooled"
    },
    {
      "x": 0,
      "y": 10,
      "z": -11,
      "name": "Void_Grass"
    },
    {
      "x": 0,
      "y": 9,
      "z": -10,
      "name": "Void_Grass"
    },
    {
      "x": 0,
      "y": 10,
      "z": -10,
      "name": "Rock_Magma_Cooled"
    },
    {
      "x": 0,
      "y": 11,
      "z": -10,
      "name": "Rock_Magma_Cooled"
    },
    {
      "x": 0,
      "y": 9,
      "z": -9,
      "name": "Void_Grass"
    },
    {
      "x": 0,
      "y": 10,
      "z": -9,
      "name": "Void_Grass"
    },
    {
      "x": 0,
      "y": 11,
      "z": -9,
      "name": "Void_Grass"
    },
    {
      "x": 0,
      "y": 12,
      "z": -9,
      "name": "Rock_Magma_Cooled"
    },
    {
      "x": 0,
      "y": 9,
      "z": -8,
      "name": "Rock_Magma_Cooled"
    },
    {
      "x": 0,
      "y": 10,
      "z": -8,
      "name": "Rock_Magma_Cooled"
    },
    {
      "x": 0,
      "y": 11,
      "z": -8,
      "name": "Rock_Magma_Cooled"
    },
    {
      "x": 0,
      "y": 12,
      "z": -8,
      "name": "Void_Grass"
    },
    {
      "x": 0,
      "y": 10,
      "z": -7,
      "name": "Rock_Magma_Cooled"
    },
    {
      "x": 0,
      "y": 11,
      "z": -7,
      "name": "Rock_Magma_Cooled"
    },
    {
      "x": 0,
      "y": 12,
      "z": -7,
      "name": "Rock_Magma_Cooled"
    },
    {
      "x": 0,
      "y": 11,
      "z": -6,
      "name": "Void_Grass"
    },
    {
      "x": 0,
      "y": 12,
      "z": -6,
      "name": "Void_Grass"
    },
    {
      "x": 0,
      "y": 13,
      "z": -6,
      "name": "Rock_Magma_Cooled"
    },
    {
      "x": 0,
      "y": 12,
      "z": -5,
      "name": "Void_Grass"
    },
    {
      "x": 0,
      "y": 13,
      "z": -5,
      "name": "Void_Grass"
    },
    {
      "x": 0,
      "y": 14,
      "z": -5,
      "name": "Void_Grass"
    },
    {
      "x": 0,
      "y": 12,
      "z": -4,
      "name": "Void_Grass"
    },
    {
      "x": 0,
      "y": 13,
      "z": -4,
      "name": "Void_Grass"
    },
    {
      "x": 0,
      "y": 14,
      "z": -4,
      "name": "Rock_Magma_Cooled"
    },
    {
      "x": 0,
      "y": 11,
      "z": -3,
      "name": "Wood_Amber_Roots"
    },
    {
      "x": 0,
      "y": 12,
      "z": -3,
      "name": "Rock_Magma_Cooled"
    },
    {
      "x": 0,
      "y": 13,
      "z": -3,
      "name": "Rock_Magma_Cooled"
    },
    {
      "x": 0,
      "y": 14,
      "z": -3,
      "name": "Void_Grass"
    },
    {
      "x": 0,
      "y": 15,
      "z": -3,
      "name": "Rock_Magma_Cooled"
    },
    {
      "x": 0,
      "y": 12,
      "z": -2,
      "name": "Wood_Azure_Roots"
    },
    {
      "x": 0,
      "y": 13,
      "z": -2,
      "name": "Void_Grass"
    },
    {
      "x": 0,
      "y": 14,
      "z": -2,
      "name": "Void_Grass"
    },
    {
      "x": 0,
      "y": 15,
      "z": -2,
      "name": "Rock_Magma_Cooled"
    },
    {
      "x": 0,
      "y": 16,
      "z": -2,
      "name": "Rock_Magma_Cooled"
    },
    {
      "x": 0,
      "y": 13,
      "z": -1,
      "name": "Rock_Crystal_Purple_Block",
      "rotation": 4
    },
    {
      "x": 0,
      "y": 14,
      "z": -1,
      "name": "Void_Grass"
    },
    {
      "x": 0,
      "y": 15,
      "z": -1,
      "name": "Void_Grass"
    },
    {
      "x": 0,
      "y": 16,
      "z": -1,
      "name": "Void_Grass"
    },
    {
      "x": 0,
      "y": 13,
      "z": 0,
      "name": "Wood_Azure_Roots"
    },
    {
      "x": 0,
      "y": 14,
      "z": 0,
      "name": "Rock_Magma_Cooled"
    },
    {
      "x": 0,
      "y": 15,
      "z": 0,
      "name": "Void_Grass"
    },
    {
      "x": 0,
      "y": 16,
      "z": 0,
      "name": "Rock_Magma_Cooled"
    },
    {
      "x": 0,
      "y": 13,
      "z": 1,
      "name": "Wood_Amber_Roots"
    },
    {
      "x": 0,
      "y": 14,
      "z": 1,
      "name": "Void_Grass"
    },
    {
      "x": 0,
      "y": 15,
      "z": 1,
      "name": "Rock_Magma_Cooled"
    },
    {
      "x": 0,
      "y": 16,
      "z": 1,
      "name": "Void_Grass"
    },
    {
      "x": 0,
      "y": 15,
      "z": 2,
      "name": "Void_Grass"
    },
    {
      "x": 0,
      "y": 16,
      "z": 2,
      "name": "Rock_Magma_Cooled"
    },
    {
      "x": 0,
      "y": 17,
      "z": 2,
      "name": "Void_Grass"
    },
    {
      "x": 0,
      "y": 14,
      "z": 3,
      "name": "Rock_Magma_Cooled"
    },
    {
      "x": 0,
      "y": 15,
      "z": 3,
      "name": "Rock_Magma_Cooled"
    },
    {
      "x": 0,
      "y": 16,
      "z": 3,
      "name": "Rock_Magma_Cooled"
    },
    {
      "x": 0,
      "y": 17,
      "z": 3,
      "name": "Void_Grass"
    },
    {
      "x": 0,
      "y": 18,
      "z": 3,
      "name": "Rock_Magma_Cooled"
    },
    {
      "x": 0,
      "y": 14,
      "z": 4,
      "name": "Void_Grass"
    },
    {
      "x": 0,
      "y": 15,
      "z": 4,
      "name": "Rock_Magma_Cooled"
    },
    {
      "x": 0,
      "y": 16,
      "z": 4,
      "name": "Void_Grass"
    },
    {
      "x": 0,
      "y": 17,
      "z": 4,
      "name": "Void_Grass"
    },
    {
      "x": 0,
      "y": 18,
      "z": 4,
      "name": "Void_Grass"
    },
    {
      "x": 0,
      "y": 13,
      "z": 5,
      "name": "Wood_Amber_Roots"
    },
    {
      "x": 0,
      "y": 14,
      "z": 5,
      "name": "Void_Grass"
    },
    {
      "x": 0,
      "y": 15,
      "z": 5,
      "name": "Void_Grass"
    },
    {
      "x": 0,
      "y": 16,
      "z": 5,
      "name": "Void_Grass"
    },
    {
      "x": 0,
      "y": 17,
      "z": 5,
      "name": "Void_Grass"
    },
    {
      "x": 0,
      "y": 18,
      "z": 5,
      "name": "Rock_Magma_Cooled"
    },
    {
      "x": 0,
      "y": 13,
      "z": 6,
      "name": "Wood_Amber_Roots"
    },
    {
      "x": 0,
      "y": 14,
      "z": 6,
      "name": "Rock_Magma_Cooled"
    },
    {
      "x": 0,
      "y": 15,
      "z": 6,
      "name": "Void_Grass"
    },
    {
      "x": 0,
      "y": 16,
      "z": 6,
      "name": "Void_Grass"
    },
    {
      "x": 0,
      "y": 17,
      "z": 6,
      "name": "Void_Grass"
    },
    {
      "x": 0,
      "y": 18,
      "z": 6,
      "name": "Rock_Magma_Cooled"
    },
    {
      "x": 0,
      "y": 14,
      "z": 7,
      "name": "Void_Grass"
    },
    {
      "x": 0,
      "y": 15,
      "z": 7,
      "name": "Rock_Magma_Cooled"
    },
    {
      "x": 0,
      "y": 16,
      "z": 7,
      "name": "Rock_Magma_Cooled"
    },
    {
      "x": 0,
      "y": 17,
      "z": 7,
      "name": "Void_Grass"
    },
    {
      "x": 0,
      "y": 18,
      "z": 7,
      "name": "Void_Grass"
    },
    {
      "x": 0,
      "y": 13,
      "z": 8,
      "name": "Wood_Azure_Roots"
    },
    {
      "x": 0,
      "y": 14,
      "z": 8,
      "name": "Rock_Crystal_Purple_Block"
    },
    {
      "x": 0,
      "y": 15,
      "z": 8,
      "name": "Void_Grass"
    },
    {
      "x": 0,
      "y": 16,
      "z": 8,
      "name": "Rock_Magma_Cooled"
    },
    {
      "x": 0,
      "y": 17,
      "z": 8,
      "name": "Rock_Magma_Cooled"
    },
    {
      "x": 0,
      "y": 14,
      "z": 9,
      "name": "Rock_Magma_Cooled"
    },
    {
      "x": 0,
      "y": 15,
      "z": 9,
      "name": "Void_Grass"
    },
    {
      "x": 0,
      "y": 16,
      "z": 9,
      "name": "Rock_Magma_Cooled"
    },
    {
      "x": 0,
      "y": 17,
      "z": 9,
      "name": "Void_Grass"
    },
    {
      "x": 0,
      "y": 15,
      "z": 10,
      "name": "Rock_Magma_Cooled"
    },
    {
      "x": 0,
      "y": 16,
      "z": 10,
      "name": "Rock_Magma_Cooled"
    },
    {
      "x": 0,
      "y": 17,
      "z": 10,
      "name": "Rock_Magma_Cooled"
    },
    {
      "x": 0,
      "y": 15,
      "z": 11,
      "name": "Void_Grass"
    },
    {
      "x": 0,
      "y": 16,
      "z": 11,
      "name": "Rock_Magma_Cooled"
    },
    {
      "x": 0,
      "y": 16,
      "z": 12,
      "name": "Rock_Magma_Cooled"
    },
    {
      "x": 1,
      "y": 10,
      "z": -10,
      "name": "Rock_Magma_Cooled"
    },
    {
      "x": 1,
      "y": 10,
      "z": -9,
      "name": "Void_Grass"
    },
    {
      "x": 1,
      "y": 11,
      "z": -9,
      "name": "Rock_Magma_Cooled"
    },
    {
      "x": 1,
      "y": 10,
      "z": -8,
      "name": "Void_Grass"
    },
    {
      "x": 1,
      "y": 11,
      "z": -8,
      "name": "Rock_Magma_Cooled"
    },
    {
      "x": 1,
      "y": 11,
      "z": -7,
      "name": "Void_Grass"
    },
    {
      "x": 1,
      "y": 13,
      "z": -5,
      "name": "Rock_Magma_Cooled"
    },
    {
      "x": 1,
      "y": 13,
      "z": -4,
      "name": "Void_Grass"
    },
    {
      "x": 1,
      "y": 13,
      "z": -3,
      "name": "Rock_Magma_Cooled"
    },
    {
      "x": 1,
      "y": 14,
      "z": -3,
      "name": "Rock_Magma_Cooled"
    },
    {
      "x": 1,
      "y": 14,
      "z": -2,
      "name": "Void_Grass"
    },
    {
      "x": 1,
      "y": 15,
      "z": -2,
      "name": "Rock_Magma_Cooled"
    },
    {
      "x": 1,
      "y": 14,
      "z": -1,
      "name": "Void_Grass"
    },
    {
      "x": 1,
      "y": 15,
      "z": -1,
      "name": "Void_Grass"
    },
    {
      "x": 1,
      "y": 16,
      "z": -1,
      "name": "Rock_Magma_Cooled"
    },
    {
      "x": 1,
      "y": 14,
      "z": 0,
      "name": "Void_Grass"
    },
    {
      "x": 1,
      "y": 15,
      "z": 0,
      "name": "Void_Grass"
    },
    {
      "x": 1,
      "y": 16,
      "z": 0,
      "name": "Void_Grass"
    },
    {
      "x": 1,
      "y": 14,
      "z": 1,
      "name": "Void_Grass"
    },
    {
      "x": 1,
      "y": 15,
      "z": 1,
      "name": "Rock_Magma_Cooled"
    },
    {
      "x": 1,
      "y": 16,
      "z": 1,
      "name": "Void_Grass"
    },
    {
      "x": 1,
      "y": 13,
      "z": 2,
      "name": "Wood_Azure_Roots"
    },
    {
      "x": 1,
      "y": 14,
      "z": 2,
      "name": "Rock_Magma_Cooled"
    },
    {
      "x": 1,
      "y": 15,
      "z": 2,
      "name": "Rock_Magma_Cooled"
    },
    {
      "x": 1,
      "y": 16,
      "z": 2,
      "name": "Void_Grass"
    },
    {
      "x": 1,
      "y": 14,
      "z": 3,
      "name": "Void_Grass"
    },
    {
      "x": 1,
      "y": 15,
      "z": 3,
      "name": "Rock_Magma_Cooled"
    },
    {
      "x": 1,
      "y": 16,
      "z": 3,
      "name": "Rock_Magma_Cooled"
    },
    {
      "x": 1,
      "y": 17,
      "z": 3,
      "name": "Rock_Magma_Cooled"
    },
    {
      "x": 1,
      "y": 14,
      "z": 4,
      "name": "Rock_Magma_Cooled"
    },
    {
      "x": 1,
      "y": 15,
      "z": 4,
      "name": "Rock_Magma_Cooled"
    },
    {
      "x": 1,
      "y": 16,
      "z": 4,
      "name": "Rock_Magma_Cooled"
    },
    {
      "x": 1,
      "y": 17,
      "z": 4,
      "name": "Void_Grass"
    },
    {
      "x": 1,
      "y": 14,
      "z": 5,
      "name": "Void_Grass"
    },
    {
      "x": 1,
      "y": 15,
      "z": 5,
      "name": "Void_Grass"
    },
    {
      "x": 1,
      "y": 16,
      "z": 5,
      "name": "Void_Grass"
    },
    {
      "x": 1,
      "y": 17,
      "z": 5,
      "name": "Void_Grass"
    },
    {
      "x": 1,
      "y": 18,
      "z": 5,
      "name": "Void_Grass"
    },
    {
      "x": 1,
      "y": 13,
      "z": 6,
      "name": "Wood_Amber_Roots"
    },
    {
      "x": 1,
      "y": 14,
      "z": 6,
      "name": "Void_Grass"
    },
    {
      "x": 1,
      "y": 15,
      "z": 6,
      "name": "Void_Grass"
    },
    {
      "x": 1,
      "y": 16,
      "z": 6,
      "name": "Rock_Magma_Cooled"
    },
    {
      "x": 1,
      "y": 17,
      "z": 6,
      "name": "Void_Grass"
    },
    {
      "x": 1,
      "y": 18,
      "z": 6,
      "name": "Rock_Magma_Cooled"
    },
    {
      "x": 1,
      "y": 13,
      "z": 7,
      "name": "Wood_Amber_Roots"
    },
    {
      "x": 1,
      "y": 14,
      "z": 7,
      "name": "Rock_Magma_Cooled"
    },
    {
      "x": 1,
      "y": 15,
      "z": 7,
      "name": "Void_Grass"
    },
    {
      "x": 1,
      "y": 16,
      "z": 7,
      "name": "Void_Grass"
    },
    {
      "x": 1,
      "y": 17,
      "z": 7,
      "name": "Rock_Magma_Cooled"
    },
    {
      "x": 1,
      "y": 18,
      "z": 7,
      "name": "Rock_Magma_Cooled"
    },
    {
      "x": 1,
      "y": 14,
      "z": 8,
      "name": "Void_Grass"
    },
    {
      "x": 1,
      "y": 15,
      "z": 8,
      "name": "Void_Grass"
    },
    {
      "x": 1,
      "y": 16,
      "z": 8,
      "name": "Void_Grass"
    },
    {
      "x": 1,
      "y": 17,
      "z": 8,
      "name": "Void_Grass"
    },
    {
      "x": 1,
      "y": 18,
      "z": 8,
      "name": "Void_Grass"
    },
    {
      "x": 1,
      "y": 14,
      "z": 9,
      "name": "Void_Grass"
    },
    {
      "x": 1,
      "y": 15,
      "z": 9,
      "name": "Rock_Magma_Cooled"
    },
    {
      "x": 1,
      "y": 16,
      "z": 9,
      "name": "Rock_Magma_Cooled"
    },
    {
      "x": 1,
      "y": 17,
      "z": 9,
      "name": "Void_Grass"
    },
    {
      "x": 1,
      "y": 18,
      "z": 9,
      "name": "Rock_Magma_Cooled"
    },
    {
      "x": 1,
      "y": 14,
      "z": 10,
      "name": "Rock_Magma_Cooled"
    },
    {
      "x": 1,
      "y": 15,
      "z": 10,
      "name": "Void_Grass"
    },
    {
      "x": 1,
      "y": 16,
      "z": 10,
      "name": "Void_Grass"
    },
    {
      "x": 1,
      "y": 17,
      "z": 10,
      "name": "Void_Grass"
    },
    {
      "x": 1,
      "y": 18,
      "z": 10,
      "name": "Rock_Magma_Cooled"
    },
    {
      "x": 1,
      "y": 14,
      "z": 11,
      "name": "Rock_Magma_Cooled"
    },
    {
      "x": 1,
      "y": 15,
      "z": 11,
      "name": "Rock_Magma_Cooled"
    },
    {
      "x": 1,
      "y": 16,
      "z": 11,
      "name": "Void_Grass"
    },
    {
      "x": 1,
      "y": 17,
      "z": 11,
      "name": "Void_Grass"
    },
    {
      "x": 1,
      "y": 15,
      "z": 12,
      "name": "Rock_Magma_Cooled"
    },
    {
      "x": 1,
      "y": 16,
      "z": 12,
      "name": "Void_Grass"
    },
    {
      "x": 1,
      "y": 17,
      "z": 12,
      "name": "Rock_Magma_Cooled"
    },
    {
      "x": 1,
      "y": 15,
      "z": 13,
      "name": "Void_Grass"
    },
    {
      "x": 1,
      "y": 16,
      "z": 13,
      "name": "Void_Grass"
    },
    {
      "x": 1,
      "y": 17,
      "z": 13,
      "name": "Rock_Magma_Cooled"
    },
    {
      "x": 1,
      "y": 15,
      "z": 14,
      "name": "Void_Grass"
    },
    {
      "x": 2,
      "y": 15,
      "z": -1,
      "name": "Rock_Magma_Cooled"
    },
    {
      "x": 2,
      "y": 15,
      "z": 0,
      "name": "Void_Grass"
    },
    {
      "x": 2,
      "y": 15,
      "z": 1,
      "name": "Rock_Magma_Cooled"
    },
    {
      "x": 2,
      "y": 14,
      "z": 2,
      "name": "Void_Grass"
    },
    {
      "x": 2,
      "y": 15,
      "z": 2,
      "name": "Void_Grass"
    },
    {
      "x": 2,
      "y": 16,
      "z": 2,
      "name": "Void_Grass"
    },
    {
      "x": 2,
      "y": 14,
      "z": 3,
      "name": "Rock_Magma_Cooled"
    },
    {
      "x": 2,
      "y": 15,
      "z": 3,
      "name": "Rock_Magma_Cooled"
    },
    {
      "x": 2,
      "y": 16,
      "z": 3,
      "name": "Rock_Magma_Cooled"
    },
    {
      "x": 2,
      "y": 17,
      "z": 3,
      "name": "Rock_Magma_Cooled"
    },
    {
      "x": 2,
      "y": 14,
      "z": 4,
      "name": "Rock_Magma_Cooled"
    },
    {
      "x": 2,
      "y": 15,
      "z": 4,
      "name": "Void_Grass"
    },
    {
      "x": 2,
      "y": 16,
      "z": 4,
      "name": "Void_Grass"
    },
    {
      "x": 2,
      "y": 17,
      "z": 4,
      "name": "Rock_Magma_Cooled"
    },
    {
      "x": 2,
      "y": 14,
      "z": 5,
      "name": "Void_Grass"
    },
    {
      "x": 2,
      "y": 15,
      "z": 5,
      "name": "Rock_Magma_Cooled"
    },
    {
      "x": 2,
      "y": 16,
      "z": 5,
      "name": "Void_Grass"
    },
    {
      "x": 2,
      "y": 17,
      "z": 5,
      "name": "Rock_Magma_Cooled"
    },
    {
      "x": 2,
      "y": 18,
      "z": 5,
      "name": "Rock_Magma_Cooled"
    },
    {
      "x": 2,
      "y": 14,
      "z": 6,
      "name": "Rock_Magma_Cooled"
    },
    {
      "x": 2,
      "y": 15,
      "z": 6,
      "name": "Void_Grass"
    },
    {
      "x": 2,
      "y": 16,
      "z": 6,
      "name": "Rock_Magma_Cooled"
    },
    {
      "x": 2,
      "y": 17,
      "z": 6,
      "name": "Rock_Magma_Cooled"
    },
    {
      "x": 2,
      "y": 18,
      "z": 6,
      "name": "Rock_Magma_Cooled"
    },
    {
      "x": 2,
      "y": 14,
      "z": 7,
      "name": "Rock_Magma_Cooled"
    },
    {
      "x": 2,
      "y": 15,
      "z": 7,
      "name": "Rock_Magma_Cooled"
    },
    {
      "x": 2,
      "y": 16,
      "z": 7,
      "name": "Rock_Magma_Cooled"
    },
    {
      "x": 2,
      "y": 17,
      "z": 7,
      "name": "Rock_Magma_Cooled"
    },
    {
      "x": 2,
      "y": 18,
      "z": 7,
      "name": "Rock_Magma_Cooled"
    },
    {
      "x": 2,
      "y": 13,
      "z": 8,
      "name": "Wood_Azure_Roots"
    },
    {
      "x": 2,
      "y": 14,
      "z": 8,
      "name": "Rock_Magma_Cooled"
    },
    {
      "x": 2,
      "y": 15,
      "z": 8,
      "name": "Rock_Magma_Cooled"
    },
    {
      "x": 2,
      "y": 16,
      "z": 8,
      "name": "Rock_Magma_Cooled"
    },
    {
      "x": 2,
      "y": 17,
      "z": 8,
      "name": "Void_Grass"
    },
    {
      "x": 2,
      "y": 18,
      "z": 8,
      "name": "Void_Grass"
    },
    {
      "x": 2,
      "y": 13,
      "z": 9,
      "name": "Wood_Amber_Roots"
    },
    {
      "x": 2,
      "y": 14,
      "z": 9,
      "name": "Void_Grass"
    },
    {
      "x": 2,
      "y": 15,
      "z": 9,
      "name": "Void_Grass"
    },
    {
      "x": 2,
      "y": 16,
      "z": 9,
      "name": "Rock_Magma_Cooled"
    },
    {
      "x": 2,
      "y": 17,
      "z": 9,
      "name": "Void_Grass"
    },
    {
      "x": 2,
      "y": 18,
      "z": 9,
      "name": "Void_Grass"
    },
    {
      "x": 2,
      "y": 14,
      "z": 10,
      "name": "Void_Grass"
    },
    {
      "x": 2,
      "y": 15,
      "z": 10,
      "name": "Rock_Magma_Cooled"
    },
    {
      "x": 2,
      "y": 16,
      "z": 10,
      "name": "Rock_Magma_Cooled"
    },
    {
      "x": 2,
      "y": 17,
      "z": 10,
      "name": "Rock_Magma_Cooled"
    },
    {
      "x": 2,
      "y": 18,
      "z": 10,
      "name": "Void_Grass"
    },
    {
      "x": 2,
      "y": 14,
      "z": 11,
      "name": "Rock_Magma_Cooled"
    },
    {
      "x": 2,
      "y": 15,
      "z": 11,
      "name": "Void_Grass"
    },
    {
      "x": 2,
      "y": 16,
      "z": 11,
      "name": "Void_Grass"
    },
    {
      "x": 2,
      "y": 17,
      "z": 11,
      "name": "Rock_Magma_Cooled"
    },
    {
      "x": 2,
      "y": 18,
      "z": 11,
      "name": "Rock_Magma_Cooled"
    },
    {
      "x": 2,
      "y": 14,
      "z": 12,
      "name": "Rock_Magma_Cooled"
    },
    {
      "x": 2,
      "y": 15,
      "z": 12,
      "name": "Rock_Magma_Cooled"
    },
    {
      "x": 2,
      "y": 16,
      "z": 12,
      "name": "Void_Grass"
    },
    {
      "x": 2,
      "y": 17,
      "z": 12,
      "name": "Rock_Magma_Cooled"
    },
    {
      "x": 2,
      "y": 18,
      "z": 12,
      "name": "Void_Grass"
    },
    {
      "x": 2,
      "y": 14,
      "z": 13,
      "name": "Rock_Magma_Cooled"
    },
    {
      "x": 2,
      "y": 15,
      "z": 13,
      "name": "Rock_Magma_Cooled"
    },
    {
      "x": 2,
      "y": 16,
      "z": 13,
      "name": "Rock_Magma_Cooled"
    },
    {
      "x": 2,
      "y": 17,
      "z": 13,
      "name": "Rock_Magma_Cooled"
    },
    {
      "x": 2,
      "y": 18,
      "z": 13,
      "name": "Rock_Magma_Cooled"
    },
    {
      "x": 2,
      "y": 14,
      "z": 14,
      "name": "Rock_Magma_Cooled"
    },
    {
      "x": 2,
      "y": 15,
      "z": 14,
      "name": "Void_Grass"
    },
    {
      "x": 2,
      "y": 16,
      "z": 14,
      "name": "Void_Grass"
    },
    {
      "x": 2,
      "y": 17,
      "z": 14,
      "name": "Rock_Magma_Cooled"
    },
    {
      "x": 2,
      "y": 14,
      "z": 15,
      "name": "Rock_Magma_Cooled"
    },
    {
      "x": 2,
      "y": 15,
      "z": 15,
      "name": "Void_Grass"
    },
    {
      "x": 2,
      "y": 14,
      "z": 16,
      "name": "Rock_Magma_Cooled"
    },
    {
      "x": 3,
      "y": 15,
      "z": 2,
      "name": "Rock_Magma_Cooled"
    },
    {
      "x": 3,
      "y": 14,
      "z": 3,
      "name": "Rock_Magma_Cooled"
    },
    {
      "x": 3,
      "y": 15,
      "z": 3,
      "name": "Rock_Magma_Cooled"
    },
    {
      "x": 3,
      "y": 16,
      "z": 3,
      "name": "Void_Grass"
    },
    {
      "x": 3,
      "y": 14,
      "z": 4,
      "name": "Void_Grass"
    },
    {
      "x": 3,
      "y": 15,
      "z": 4,
      "name": "Void_Grass"
    },
    {
      "x": 3,
      "y": 16,
      "z": 4,
      "name": "Void_Grass"
    },
    {
      "x": 3,
      "y": 17,
      "z": 4,
      "name": "Rock_Magma_Cooled"
    },
    {
      "x": 3,
      "y": 14,
      "z": 5,
      "name": "Void_Grass"
    },
    {
      "x": 3,
      "y": 15,
      "z": 5,
      "name": "Rock_Magma_Cooled"
    },
    {
      "x": 3,
      "y": 16,
      "z": 5,
      "name": "Rock_Magma_Cooled"
    },
    {
      "x": 3,
      "y": 17,
      "z": 5,
      "name": "Void_Grass"
    },
    {
      "x": 3,
      "y": 15,
      "z": 6,
      "name": "Void_Grass"
    },
    {
      "x": 3,
      "y": 16,
      "z": 6,
      "name": "Rock_Magma_Cooled"
    },
    {
      "x": 3,
      "y": 17,
      "z": 6,
      "name": "Void_Grass"
    },
    {
      "x": 3,
      "y": 15,
      "z": 7,
      "name": "Rock_Magma_Cooled"
    },
    {
      "x": 3,
      "y": 16,
      "z": 7,
      "name": "Void_Grass"
    },
    {
      "x": 3,
      "y": 17,
      "z": 7,
      "name": "Rock_Magma_Cooled"
    },
    {
      "x": 3,
      "y": 15,
      "z": 8,
      "name": "Void_Grass"
    },
    {
      "x": 3,
      "y": 16,
      "z": 8,
      "name": "Rock_Magma_Cooled"
    },
    {
      "x": 3,
      "y": 17,
      "z": 8,
      "name": "Rock_Magma_Cooled"
    },
    {
      "x": 3,
      "y": 18,
      "z": 8,
      "name": "Rock_Magma_Cooled"
    },
    {
      "x": 3,
      "y": 13,
      "z": 9,
      "name": "Wood_Amber_Roots"
    },
    {
      "x": 3,
      "y": 14,
      "z": 9,
      "name": "Void_Grass"
    },
    {
      "x": 3,
      "y": 15,
      "z": 9,
      "name": "Rock_Magma_Cooled"
    },
    {
      "x": 3,
      "y": 16,
      "z": 9,
      "name": "Rock_Magma_Cooled"
    },
    {
      "x": 3,
      "y": 17,
      "z": 9,
      "name": "Void_Grass"
    },
    {
      "x": 3,
      "y": 18,
      "z": 9,
      "name": "Void_Grass"
    },
    {
      "x": 3,
      "y": 13,
      "z": 10,
      "name": "Wood_Amber_Roots"
    },
    {
      "x": 3,
      "y": 14,
      "z": 10,
      "name": "Void_Grass"
    },
    {
      "x": 3,
      "y": 15,
      "z": 10,
      "name": "Rock_Magma_Cooled"
    },
    {
      "x": 3,
      "y": 16,
      "z": 10,
      "name": "Void_Grass"
    },
    {
      "x": 3,
      "y": 17,
      "z": 10,
      "name": "Void_Grass"
    },
    {
      "x": 3,
      "y": 18,
      "z": 10,
      "name": "Void_Grass"
    },
    {
      "x": 3,
      "y": 13,
      "z": 11,
      "name": "Wood_Amber_Roots"
    },
    {
      "x": 3,
      "y": 14,
      "z": 11,
      "name": "Rock_Magma_Cooled"
    },
    {
      "x": 3,
      "y": 15,
      "z": 11,
      "name": "Void_Grass"
    },
    {
      "x": 3,
      "y": 16,
      "z": 11,
      "name": "Rock_Magma_Cooled"
    },
    {
      "x": 3,
      "y": 17,
      "z": 11,
      "name": "Rock_Magma_Cooled"
    },
    {
      "x": 3,
      "y": 18,
      "z": 11,
      "name": "Rock_Magma_Cooled"
    },
    {
      "x": 3,
      "y": 12,
      "z": 12,
      "name": "Wood_Azure_Roots"
    },
    {
      "x": 3,
      "y": 13,
      "z": 12,
      "name": "Void_Grass"
    },
    {
      "x": 3,
      "y": 14,
      "z": 12,
      "name": "Void_Grass"
    },
    {
      "x": 3,
      "y": 15,
      "z": 12,
      "name": "Void_Grass"
    },
    {
      "x": 3,
      "y": 16,
      "z": 12,
      "name": "Rock_Magma_Cooled"
    },
    {
      "x": 3,
      "y": 17,
      "z": 12,
      "name": "Rock_Magma_Cooled"
    },
    {
      "x": 3,
      "y": 18,
      "z": 12,
      "name": "Void_Grass"
    },
    {
      "x": 3,
      "y": 13,
      "z": 13,
      "name": "Void_Grass"
    },
    {
      "x": 3,
      "y": 14,
      "z": 13,
      "name": "Void_Grass"
    },
    {
      "x": 3,
      "y": 15,
      "z": 13,
      "name": "Rock_Magma_Cooled"
    },
    {
      "x": 3,
      "y": 16,
      "z": 13,
      "name": "Void_Grass"
    },
    {
      "x": 3,
      "y": 17,
      "z": 13,
      "name": "Rock_Magma_Cooled"
    },
    {
      "x": 3,
      "y": 18,
      "z": 13,
      "name": "Rock_Magma_Cooled"
    },
    {
      "x": 3,
      "y": 13,
      "z": 14,
      "name": "Void_Grass"
    },
    {
      "x": 3,
      "y": 14,
      "z": 14,
      "name": "Void_Grass"
    },
    {
      "x": 3,
      "y": 15,
      "z": 14,
      "name": "Rock_Magma_Cooled"
    },
    {
      "x": 3,
      "y": 16,
      "z": 14,
      "name": "Rock_Magma_Cooled"
    },
    {
      "x": 3,
      "y": 17,
      "z": 14,
      "name": "Rock_Magma_Cooled"
    },
    {
      "x": 3,
      "y": 13,
      "z": 15,
      "name": "Rock_Magma_Cooled"
    },
    {
      "x": 3,
      "y": 14,
      "z": 15,
      "name": "Rock_Magma_Cooled"
    },
    {
      "x": 3,
      "y": 15,
      "z": 15,
      "name": "Void_Grass"
    },
    {
      "x": 3,
      "y": 16,
      "z": 15,
      "name": "Void_Grass"
    },
    {
      "x": 3,
      "y": 13,
      "z": 16,
      "name": "Void_Grass"
    },
    {
      "x": 3,
      "y": 14,
      "z": 16,
      "name": "Rock_Magma_Cooled"
    },
    {
      "x": 3,
      "y": 15,
      "z": 16,
      "name": "Void_Grass"
    },
    {
      "x": 3,
      "y": 14,
      "z": 17,
      "name": "Void_Grass"
    },
    {
      "x": 4,
      "y": 16,
      "z": 4,
      "name": "Rock_Magma_Cooled"
    },
    {
      "x": 4,
      "y": 16,
      "z": 5,
      "name": "Rock_Magma_Cooled"
    },
    {
      "x": 4,
      "y": 16,
      "z": 6,
      "name": "Rock_Magma_Cooled"
    },
    {
      "x": 4,
      "y": 15,
      "z": 7,
      "name": "Void_Grass"
    },
    {
      "x": 4,
      "y": 16,
      "z": 7,
      "name": "Void_Grass"
    },
    {
      "x": 4,
      "y": 17,
      "z": 7,
      "name": "Rock_Magma_Cooled"
    },
    {
      "x": 4,
      "y": 15,
      "z": 8,
      "name": "Rock_Magma_Cooled"
    },
    {
      "x": 4,
      "y": 16,
      "z": 8,
      "name": "Void_Grass"
    },
    {
      "x": 4,
      "y": 17,
      "z": 8,
      "name": "Void_Grass"
    },
    {
      "x": 4,
      "y": 14,
      "z": 9,
      "name": "Void_Grass"
    },
    {
      "x": 4,
      "y": 15,
      "z": 9,
      "name": "Rock_Magma_Cooled"
    },
    {
      "x": 4,
      "y": 16,
      "z": 9,
      "name": "Void_Grass"
    },
    {
      "x": 4,
      "y": 17,
      "z": 9,
      "name": "Void_Grass"
    },
    {
      "x": 4,
      "y": 13,
      "z": 10,
      "name": "Plant_Vine_Wall_Dead",
      "support": 15,
      "rotation": 2
    },
    {
      "x": 4,
      "y": 14,
      "z": 10,
      "name": "Rock_Magma_Cooled"
    },
    {
      "x": 4,
      "y": 15,
      "z": 10,
      "name": "Rock_Magma_Cooled"
    },
    {
      "x": 4,
      "y": 16,
      "z": 10,
      "name": "Rock_Magma_Cooled"
    },
    {
      "x": 4,
      "y": 17,
      "z": 10,
      "name": "Void_Grass"
    },
    {
      "x": 4,
      "y": 13,
      "z": 11,
      "name": "Rock_Magma_Cooled"
    },
    {
      "x": 4,
      "y": 14,
      "z": 11,
      "name": "Rock_Magma_Cooled"
    },
    {
      "x": 4,
      "y": 15,
      "z": 11,
      "name": "Void_Grass"
    },
    {
      "x": 4,
      "y": 16,
      "z": 11,
      "name": "Rock_Magma_Cooled"
    },
    {
      "x": 4,
      "y": 17,
      "z": 11,
      "name": "Void_Grass"
    },
    {
      "x": 4,
      "y": 18,
      "z": 11,
      "name": "Void_Grass"
    },
    {
      "x": 4,
      "y": 12,
      "z": 12,
      "name": "Void_Grass"
    },
    {
      "x": 4,
      "y": 13,
      "z": 12,
      "name": "Rock_Magma_Cooled"
    },
    {
      "x": 4,
      "y": 14,
      "z": 12,
      "name": "Void_Grass"
    },
    {
      "x": 4,
      "y": 15,
      "z": 12,
      "name": "Void_Grass"
    },
    {
      "x": 4,
      "y": 16,
      "z": 12,
      "name": "Rock_Magma_Cooled"
    },
    {
      "x": 4,
      "y": 17,
      "z": 12,
      "name": "Void_Grass"
    },
    {
      "x": 4,
      "y": 18,
      "z": 12,
      "name": "Rock_Magma_Cooled"
    },
    {
      "x": 4,
      "y": 11,
      "z": 13,
      "name": "Wood_Amber_Roots"
    },
    {
      "x": 4,
      "y": 12,
      "z": 13,
      "name": "Void_Grass"
    },
    {
      "x": 4,
      "y": 13,
      "z": 13,
      "name": "Rock_Magma_Cooled"
    },
    {
      "x": 4,
      "y": 14,
      "z": 13,
      "name": "Void_Grass"
    },
    {
      "x": 4,
      "y": 15,
      "z": 13,
      "name": "Void_Grass"
    },
    {
      "x": 4,
      "y": 16,
      "z": 13,
      "name": "Void_Grass"
    },
    {
      "x": 4,
      "y": 17,
      "z": 13,
      "name": "Void_Grass"
    },
    {
      "x": 4,
      "y": 18,
      "z": 13,
      "name": "Rock_Magma_Cooled"
    },
    {
      "x": 4,
      "y": 12,
      "z": 14,
      "name": "Rock_Magma_Cooled"
    },
    {
      "x": 4,
      "y": 13,
      "z": 14,
      "name": "Rock_Magma_Cooled"
    },
    {
      "x": 4,
      "y": 14,
      "z": 14,
      "name": "Void_Grass"
    },
    {
      "x": 4,
      "y": 15,
      "z": 14,
      "name": "Void_Grass"
    },
    {
      "x": 4,
      "y": 16,
      "z": 14,
      "name": "Void_Grass"
    },
    {
      "x": 4,
      "y": 17,
      "z": 14,
      "name": "Rock_Magma_Cooled"
    },
    {
      "x": 4,
      "y": 11,
      "z": 15,
      "name": "Wood_Amber_Roots"
    },
    {
      "x": 4,
      "y": 12,
      "z": 15,
      "name": "Void_Grass"
    },
    {
      "x": 4,
      "y": 13,
      "z": 15,
      "name": "Rock_Magma_Cooled"
    },
    {
      "x": 4,
      "y": 14,
      "z": 15,
      "name": "Rock_Magma_Cooled"
    },
    {
      "x": 4,
      "y": 15,
      "z": 15,
      "name": "Rock_Magma_Cooled"
    },
    {
      "x": 4,
      "y": 16,
      "z": 15,
      "name": "Rock_Magma_Cooled"
    },
    {
      "x": 4,
      "y": 12,
      "z": 16,
      "name": "Rock_Magma_Cooled"
    },
    {
      "x": 4,
      "y": 13,
      "z": 16,
      "name": "Void_Grass"
    },
    {
      "x": 4,
      "y": 14,
      "z": 16,
      "name": "Rock_Magma_Cooled"
    },
    {
      "x": 4,
      "y": 15,
      "z": 16,
      "name": "Void_Grass"
    },
    {
      "x": 4,
      "y": 12,
      "z": 17,
      "name": "Void_Grass"
    },
    {
      "x": 4,
      "y": 13,
      "z": 17,
      "name": "Rock_Magma_Cooled"
    },
    {
      "x": 4,
      "y": 14,
      "z": 17,
      "name": "Void_Grass"
    },
    {
      "x": 4,
      "y": 15,
      "z": 17,
      "name": "Rock_Magma_Cooled"
    },
    {
      "x": 4,
      "y": 14,
      "z": 18,
      "name": "Void_Grass"
    },
    {
      "x": 5,
      "y": 16,
      "z": 7,
      "name": "Void_Grass"
    },
    {
      "x": 5,
      "y": 16,
      "z": 8,
      "name": "Rock_Magma_Cooled"
    },
    {
      "x": 5,
      "y": 15,
      "z": 9,
      "name": "Void_Grass"
    },
    {
      "x": 5,
      "y": 16,
      "z": 9,
      "name": "Void_Grass"
    },
    {
      "x": 5,
      "y": 15,
      "z": 10,
      "name": "Void_Grass"
    },
    {
      "x": 5,
      "y": 16,
      "z": 10,
      "name": "Void_Grass"
    },
    {
      "x": 5,
      "y": 17,
      "z": 10,
      "name": "Void_Grass"
    },
    {
      "x": 5,
      "y": 12,
      "z": 11,
      "name": "Wood_Azure_Roots"
    },
    {
      "x": 5,
      "y": 13,
      "z": 11,
      "name": "Void_Grass"
    },
    {
      "x": 5,
      "y": 14,
      "z": 11,
      "name": "Void_Grass"
    },
    {
      "x": 5,
      "y": 15,
      "z": 11,
      "name": "Rock_Magma_Cooled"
    },
    {
      "x": 5,
      "y": 16,
      "z": 11,
      "name": "Void_Grass"
    },
    {
      "x": 5,
      "y": 17,
      "z": 11,
      "name": "Rock_Magma_Cooled"
    },
    {
      "x": 5,
      "y": 11,
