{
  "version": 8,
  "blockIdVersion": 11,
  "anchorX": 0,
  "anchorY": 0,
  "anchorZ": 0,
  "blocks": [
    {
      "x": -3,
      "y": 17,
      "z": 1,
      "name": "Plant_Leaves_Dead"
    },
    {
      "x": -3,
      "y": 18,
      "z": 1,
      "name": "Plant_Leaves_Dead"
    },
    {
      "x": -2,
      "y": 12,
      "z": 0,
      "name": "Plant_Leaves_Dead"
    },
    {
      "x": -2,
      "y": 18,
      "z": 0,
      "name": "Plant_Leaves_Dead"
    },
    {
      "x": -2,
      "y": 21,
      "z": 0,
      "name": "Plant_Leaves_Dead"
    },
    {
      "x": -2,
      "y": 9,
      "z": 1,
      "name": "Plant_Leaves_Dead"
    },
    {
      "x": -2,
      "y": 12,
      "z": 1,
      "name": "Plant_Leaves_Dead"
    },
    {
      "x": -2,
      "y": 17,
      "z": 1,
      "name": "Plant_Leaves_Dead"
    },
    {
      "x": -2,
      "y": 18,
      "z": 1,
      "name": "Plant_Leaves_Dead"
    },
    {
      "x": -2,
      "y": 21,
      "z": 1,
      "name": "Plant_Leaves_Dead"
    },
    {
      "x": -2,
      "y": 22,
      "z": 1,
      "name": "Plant_Leaves_Dead"
    },
    {
      "x": -2,
      "y": 18,
      "z": 2,
      "name": "Plant_Leaves_Dead"
    },
    {
      "x": -2,
      "y": 20,
      "z": 2,
      "name": "Plant_Leaves_Dead"
    },
    {
      "x": -1,
      "y": 13,
      "z": -1,
      "name": "Plant_Leaves_Dead"
    },
    {
      "x": -1,
      "y": 19,
      "z": -1,
      "name": "Plant_Leaves_Dead"
    },
    {
      "x": -1,
      "y": 9,
      "z": 0,
      "name": "Plant_Leaves_Dead"
    },
    {
      "x": -1,
      "y": 13,
      "z": 0,
      "name": "Plant_Leaves_Dead"
    },
    {
      "x": -1,
      "y": 21,
      "z": 0,
      "name": "Plant_Leaves_Dead"
    },
    {
      "x": -1,
      "y": 9,
      "z": 1,
      "name": "Wood_Ash_Branch_Long",
      "rotation": 5
    },
    {
      "x": -1,
      "y": 10,
      "z": 1,
      "name": "Plant_Leaves_Dead"
    },
    {
      "x": -1,
      "y": 12,
      "z": 1,
      "name": "Wood_Ash_Branch_Corner",
      "rotation": 3
    },
    {
      "x": -1,
      "y": 13,
      "z": 1,
      "name": "Plant_Leaves_Dead"
    },
    {
      "x": -1,
      "y": 18,
      "z": 1,
      "name": "Wood_Ash_Branch_Long",
      "rotation": 5
    },
    {
      "x": -1,
      "y": 21,
      "z": 1,
      "name": "Wood_Ash_Branch_Corner",
      "rotation": 3
    },
    {
      "x": -1,
      "y": 22,
      "z": 1,
      "name": "Plant_Leaves_Dead"
    },
    {
      "x": -1,
      "y": 9,
      "z": 2,
      "name": "Plant_Leaves_Dead"
    },
    {
      "x": -1,
      "y": 12,
      "z": 2,
      "name": "Plant_Leaves_Dead"
    },
    {
      "x": -1,
      "y": 18,
      "z": 2,
      "name": "Plant_Leaves_Dead"
    },
    {
      "x": -1,
      "y": 20,
      "z": 2,
      "name": "Plant_Leaves_Dead"
    },
    {
      "x": -1,
      "y": 21,
      "z": 2,
      "name": "Plant_Leaves_Dead"
    },
    {
      "x": -1,
      "y": 20,
      "z": 3,
      "name": "Plant_Leaves_Dead"
    },
    {
      "x": -1,
      "y": 21,
      "z": 3,
      "name": "Plant_Leaves_Dead"
    },
    {
      "x": 0,
      "y": 12,
      "z": -4,
      "name": "Plant_Leaves_Dead"
    },
    {
      "x": 0,
      "y": 12,
      "z": -3,
      "name": "Plant_Leaves_Dead"
    },
    {
      "x": 0,
      "y": 12,
      "z": -2,
      "name": "Plant_Leaves_Dead"
    },
    {
      "x": 0,
      "y": 16,
      "z": -2,
      "name": "Plant_Leaves_Dead"
    },
    {
      "x": 0,
      "y": 19,
      "z": -2,
      "name": "Plant_Leaves_Dead"
    },
    {
      "x": 0,
      "y": 13,
      "z": -1,
      "name": "Plant_Leaves_Dead"
    },
    {
      "x": 0,
      "y": 19,
      "z": -1,
      "name": "Plant_Leaves_Dead"
    },
    {
      "x": 0,
      "y": 19,
      "z": 0,
      "name": "Plant_Leaves_Dead"
    },
    {
      "x": 0,
      "y": 22,
      "z": 0,
      "name": "Plant_Leaves_Dead"
    },
    {
      "x": 0,
      "y": 23,
      "z": 0,
      "name": "Plant_Leaves_Dead"
    },
    {
      "x": 0,
      "y": 9,
      "z": 1,
      "name": "Wood_Ash_Branch_Long",
      "rotation": 5
    },
    {
      "x": 0,
      "y": 12,
      "z": 1,
      "name": "Wood_Ash_Branch_Long",
      "rotation": 5
    },
    {
      "x": 0,
      "y": 15,
      "z": 1,
      "name": "Wood_Ash_Branch_Long",
      "rotation": 5
    },
    {
      "x": 0,
      "y": 18,
      "z": 1,
      "name": "Wood_Ash_Branch_Long",
      "rotation": 5
    },
    {
      "x": 0,
      "y": 21,
      "z": 1,
      "name": "Wood_Ash_Branch_Long",
      "rotation": 5
    },
    {
      "x": 0,
      "y": 22,
      "z": 1,
      "name": "Plant_Leaves_Dead"
    },
    {
      "x": 0,
      "y": 23,
      "z": 1,
      "name": "Plant_Leaves_Dead"
    },
    {
      "x": 0,
      "y": 9,
      "z": 2,
      "name": "Plant_Leaves_Dead"
    },
    {
      "x": 0,
      "y": 23,
      "z": 2,
      "name": "Plant_Leaves_Dead"
    },
    {
      "x": 0,
      "y": 11,
      "z": 3,
      "name": "Plant_Leaves_Dead"
    },
    {
      "x": 0,
      "y": 16,
      "z": 3,
      "name": "Plant_Leaves_Dead"
    },
    {
      "x": 0,
      "y": 22,
      "z": 3,
      "name": "Plant_Leaves_Dead"
    },
    {
      "x": 0,
      "y": 11,
      "z": 4,
      "name": "Plant_Leaves_Dead"
    },
    {
      "x": 0,
      "y": 20,
      "z": 4,
      "name": "Plant_Leaves_Dead"
    },
    {
      "x": 1,
      "y": 12,
      "z": -4,
      "name": "Plant_Leaves_Dead"
    },
    {
      "x": 1,
      "y": 12,
      "z": -3,
      "name": "Plant_Leaves_Dead"
    },
    {
      "x": 1,
      "y": 13,
      "z": -3,
      "name": "Plant_Leaves_Dead"
    },
    {
      "x": 1,
      "y": 15,
      "z": -3,
      "name": "Plant_Leaves_Dead"
    },
    {
      "x": 1,
      "y": 10,
      "z": -2,
      "name": "Plant_Leaves_Dead"
    },
    {
      "x": 1,
      "y": 12,
      "z": -2,
      "name": "Wood_Ash_Branch_Long",
      "rotation": 4
    },
    {
      "x": 1,
      "y": 13,
      "z": -2,
      "name": "Plant_Leaves_Dead"
    },
    {
      "x": 1,
      "y": 16,
      "z": -2,
      "name": "Plant_Leaves_Dead"
    },
    {
      "x": 1,
      "y": 19,
      "z": -2,
      "name": "Plant_Leaves_Dead"
    },
    {
      "x": 1,
      "y": 10,
      "z": -1,
      "name": "Wood_Ash_Branch_Long",
      "rotation": 4
    },
    {
      "x": 1,
      "y": 11,
      "z": -1,
      "name": "Plant_Leaves_Dead"
    },
    {
      "x": 1,
      "y": 12,
      "z": -1,
      "name": "Wood_Ash_Branch_Long",
      "rotation": 4
    },
    {
      "x": 1,
      "y": 15,
      "z": -1,
      "name": "Wood_Ash_Branch_Long",
      "rotation": 4
    },
    {
      "x": 1,
      "y": 16,
      "z": -1,
      "name": "Plant_Leaves_Dead"
    },
    {
      "x": 1,
      "y": 19,
      "z": -1,
      "name": "Wood_Ash_Branch_Long",
      "rotation": 4
    },
    {
      "x": 1,
      "y": 20,
      "z": -1,
      "name": "Plant_Leaves_Dead"
    },
    {
      "x": 1,
      "y": 22,
      "z": -1,
      "name": "Plant_Leaves_Dead"
    },
    {
      "x": 1,
      "y": 23,
      "z": -1,
      "name": "Plant_Leaves_Dead"
    },
    {
      "x": 1,
      "y": 10,
      "z": 0,
      "name": "Wood_Ash_Branch_Long",
      "rotation": 4
    },
    {
      "x": 1,
      "y": 12,
      "z": 0,
      "name": "Wood_Ash_Branch_Long",
      "rotation": 4
    },
    {
      "x": 1,
      "y": 14,
      "z": 0,
      "name": "Wood_Ash_Branch_Long",
      "rotation": 4
    },
    {
      "x": 1,
      "y": 15,
      "z": 0,
      "name": "Wood_Ash_Branch_Long",
      "rotation": 4
    },
    {
      "x": 1,
      "y": 16,
      "z": 0,
      "name": "Plant_Leaves_Dead"
    },
    {
      "x": 1,
      "y": 19,
      "z": 0,
      "name": "Wood_Ash_Branch_Long",
      "rotation": 4
    },
    {
      "x": 1,
      "y": 22,
      "z": 0,
      "name": "Wood_Ash_Branch_Corner",
      "rotation": 2
    },
    {
      "x": 1,
      "y": 0,
      "z": 1,
      "name": "Wood_Ash_Trunk_Full"
    },
    {
      "x": 1,
      "y": 1,
      "z": 1,
      "name": "Wood_Ash_Trunk_Full"
    },
    {
      "x": 1,
      "y": 2,
      "z": 1,
      "name": "Wood_Ash_Trunk_Full"
    },
    {
      "x": 1,
      "y": 3,
      "z": 1,
      "name": "Wood_Ash_Trunk_Full"
    },
    {
      "x": 1,
      "y": 4,
      "z": 1,
      "name": "Wood_Ash_Trunk_Full"
    },
    {
      "x": 1,
      "y": 5,
      "z": 1,
      "name": "Wood_Ash_Trunk_Full"
    },
    {
      "x": 1,
      "y": 6,
      "z": 1,
      "name": "Wood_Ash_Trunk_Full"
    },
    {
      "x": 1,
      "y": 7,
      "z": 1,
      "name": "Wood_Ash_Trunk_Full"
    },
    {
      "x": 1,
      "y": 8,
      "z": 1,
      "name": "Wood_Ash_Trunk_Full"
    },
    {
      "x": 1,
      "y": 9,
      "z": 1,
      "name": "Wood_Ash_Trunk_Full"
    },
    {
      "x": 1,
      "y": 10,
      "z": 1,
      "name": "Wood_Ash_Trunk_Full"
    },
    {
      "x": 1,
      "y": 11,
      "z": 1,
      "name": "Wood_Ash_Trunk_Full"
    },
    {
      "x": 1,
      "y": 12,
      "z": 1,
      "name": "Wood_Ash_Trunk_Full"
    },
    {
      "x": 1,
      "y": 13,
      "z": 1,
      "name": "Wood_Ash_Trunk_Full"
    },
    {
      "x": 1,
      "y": 14,
      "z": 1,
      "name": "Wood_Ash_Trunk_Full"
    },
    {
      "x": 1,
      "y": 15,
      "z": 1,
      "name": "Wood_Ash_Trunk_Full"
    },
    {
      "x": 1,
      "y": 16,
      "z": 1,
      "name": "Wood_Ash_Trunk_Full"
    },
    {
      "x": 1,
      "y": 17,
      "z": 1,
      "name": "Wood_Ash_Trunk_Full"
    },
    {
      "x": 1,
      "y": 18,
      "z": 1,
      "name": "Wood_Ash_Trunk_Full"
    },
    {
      "x": 1,
      "y": 19,
      "z": 1,
      "name": "Wood_Ash_Trunk_Full"
    },
    {
      "x": 1,
      "y": 20,
      "z": 1,
      "name": "Wood_Ash_Trunk_Full"
    },
    {
      "x": 1,
      "y": 21,
      "z": 1,
      "name": "Wood_Ash_Trunk_Full"
    },
    {
      "x": 1,
      "y": 22,
      "z": 1,
      "name": "Wood_Ash_Trunk_Full"
    },
    {
      "x": 1,
      "y": 23,
      "z": 1,
      "name": "Wood_Ash_Trunk_Full"
    },
    {
      "x": 1,
      "y": 24,
      "z": 1,
      "name": "Plant_Leaves_Dead"
    },
    {
      "x": 1,
      "y": 6,
      "z": 2,
      "name": "Wood_Ash_Branch_Long",
      "rotation": 4
    },
    {
      "x": 1,
      "y": 11,
      "z": 2,
      "name": "Wood_Ash_Branch_Long",
      "rotation": 4
    },
    {
      "x": 1,
      "y": 15,
      "z": 2,
      "name": "Wood_Ash_Branch_Long",
      "rotation": 4
    },
    {
      "x": 1,
      "y": 16,
      "z": 2,
      "name": "Wood_Ash_Branch_Long",
      "rotation": 4
    },
    {
      "x": 1,
      "y": 20,
      "z": 2,
      "name": "Wood_Ash_Branch_Long",
      "rotation": 4
    },
    {
      "x": 1,
      "y": 22,
      "z": 2,
      "name": "Wood_Ash_Branch_Long",
      "rotation": 4
    },
    {
      "x": 1,
      "y": 23,
      "z": 2,
      "name": "Plant_Leaves_Dead"
    },
    {
      "x": 1,
      "y": 11,
      "z": 3,
      "name": "Wood_Ash_Branch_Corner"
    },
    {
      "x": 1,
      "y": 12,
      "z": 3,
      "name": "Plant_Leaves_Dead"
    },
    {
      "x": 1,
      "y": 15,
      "z": 3,
      "name": "Plant_Leaves_Dead"
    },
    {
      "x": 1,
      "y": 16,
      "z": 3,
      "name": "Wood_Ash_Branch_Long",
      "rotation": 4
    },
    {
      "x": 1,
      "y": 17,
      "z": 3,
      "name": "Plant_Leaves_Dead"
    },
    {
      "x": 1,
      "y": 20,
      "z": 3,
      "name": "Wood_Ash_Branch_Long",
      "rotation": 4
    },
    {
      "x": 1,
      "y": 21,
      "z": 3,
      "name": "Plant_Leaves_Dead"
    },
    {
      "x": 1,
      "y": 22,
      "z": 3,
      "name": "Plant_Leaves_Dead"
    },
    {
      "x": 1,
      "y": 11,
      "z": 4,
      "name": "Plant_Leaves_Dead"
    },
    {
      "x": 1,
      "y": 16,
      "z": 4,
      "name": "Plant_Leaves_Dead"
    },
    {
      "x": 1,
      "y": 20,
      "z": 4,
      "name": "Plant_Leaves_Dead"
    },
    {
      "x": 1,
      "y": 21,
      "z": 4,
      "name": "Plant_Leaves_Dead"
    },
    {
      "x": 2,
      "y": 12,
      "z": -3,
      "name": "Plant_Leaves_Dead"
    },
    {
      "x": 2,
      "y": 16,
      "z": -3,
      "name": "Plant_Leaves_Dead"
    },
    {
      "x": 2,
      "y": 10,
      "z": -2,
      "name": "Plant_Leaves_Dead"
    },
    {
      "x": 2,
      "y": 12,
      "z": -2,
      "name": "Plant_Leaves_Dead"
    },
    {
      "x": 2,
      "y": 16,
      "z": -2,
      "name": "Plant_Leaves_Dead"
    },
    {
      "x": 2,
      "y": 10,
      "z": -1,
      "name": "Plant_Leaves_Dead"
    },
    {
      "x": 2,
      "y": 15,
      "z": -1,
      "name": "Plant_Leaves_Dead"
    },
    {
      "x": 2,
      "y": 19,
      "z": -1,
      "name": "Plant_Leaves_Dead"
    },
    {
      "x": 2,
      "y": 22,
      "z": -1,
      "name": "Plant_Leaves_Dead"
    },
    {
      "x": 2,
      "y": 13,
      "z": 0,
      "name": "Plant_Leaves_Dead"
    },
    {
      "x": 2,
      "y": 15,
      "z": 0,
      "name": "Plant_Leaves_Dead"
    },
    {
      "x": 2,
      "y": 22,
      "z": 0,
      "name": "Plant_Leaves_Dead"
    },
    {
      "x": 2,
      "y": 5,
      "z": 1,
      "name": "Wood_Ash_Branch_Long",
      "rotation": 5
    },
    {
      "x": 2,
      "y": 13,
      "z": 1,
      "name": "Wood_Ash_Branch_Long",
      "rotation": 5
    },
    {
      "x": 2,
      "y": 18,
      "z": 1,
      "name": "Wood_Ash_Branch_Long",
      "rotation": 5
    },
    {
      "x": 2,
      "y": 19,
      "z": 1,
      "name": "Plant_Leaves_Dead"
    },
    {
      "x": 2,
      "y": 22,
      "z": 1,
      "name": "Plant_Leaves_Dead"
    },
    {
      "x": 2,
      "y": 23,
      "z": 1,
      "name": "Plant_Leaves_Dead"
    },
    {
      "x": 2,
      "y": 22,
      "z": 2,
      "name": "Plant_Leaves_Dead"
    },
    {
      "x": 2,
      "y": 11,
      "z": 3,
      "name": "Plant_Leaves_Dead"
    },
    {
      "x": 2,
      "y": 13,
      "z": 3,
      "name": "Plant_Leaves_Dead"
    },
    {
      "x": 2,
      "y": 16,
      "z": 3,
      "name": "Plant_Leaves_Dead"
    },
    {
      "x": 2,
      "y": 20,
      "z": 3,
      "name": "Plant_Leaves_Dead"
    },
    {
      "x": 2,
      "y": 22,
      "z": 3,
      "name": "Plant_Leaves_Dead"
    },
    {
      "x": 2,
      "y": 11,
      "z": 4,
      "name": "Plant_Leaves_Dead"
    },
    {
      "x": 2,
      "y": 12,
      "z": 4,
      "name": "Plant_Leaves_Dead"
    },
    {
      "x": 2,
      "y": 20,
      "z": 4,
      "name": "Plant_Leaves_Dead"
    },
    {
      "x": 3,
      "y": 10,
      "z": -2,
      "name": "Plant_Leaves_Dead"
    },
    {
      "x": 3,
      "y": 10,
      "z": -1,
      "name": "Plant_Leaves_Dead"
    },
    {
      "x": 3,
      "y": 21,
      "z": -1,
      "name": "Plant_Leaves_Dead"
    },
    {
      "x": 3,
      "y": 13,
      "z": 0,
      "name": "Plant_Leaves_Dead"
    },
    {
      "x": 3,
      "y": 19,
      "z": 0,
      "name": "Plant_Leaves_Dead"
    },
    {
      "x": 3,
      "y": 13,
      "z": 1,
      "name": "Wood_Ash_Branch_Long",
      "rotation": 5
    },
    {
      "x": 3,
      "y": 14,
      "z": 1,
      "name": "Plant_Leaves_Dead"
    },
    {
      "x": 3,
      "y": 18,
      "z": 1,
      "name": "Wood_Ash_Branch_Corner",
      "rotation": 1
    },
    {
      "x": 3,
      "y": 19,
      "z": 1,
      "name": "Plant_Leaves_Dead"
    },
    {
      "x": 3,
      "y": 13,
      "z": 2,
      "name": "Plant_Leaves_Dead"
    },
    {
      "x": 3,
      "y": 18,
      "z": 2,
      "name": "Plant_Leaves_Dead"
    },
    {
      "x": 4,
      "y": 19,
      "z": 0,
      "name": "Plant_Leaves_Dead"
    },
    {
      "x": 4,
      "y": 13,
      "z": 1,
      "name": "Plant_Leaves_Dead"
    },
    {
      "x": 4,
      "y": 19,
      "z": 1,
      "name": "Plant_Leaves_Dead"
    },
    {
      "x": 4,
      "y": 18,
      "z": 2,
      "name": "Plant_Leaves_Dead"
    }
  ],
  "fluids": [
    {
      "x": -3,
      "y": 17,
      "z": 1,
      "name": "Empty",
      "level": 0
    },
    {
      "x": -3,
      "y": 18,
      "z": 1,
      "name": "Empty",
      "level": 0
    },
    {
      "x": -2,
      "y": 12,
      "z": 0,
      "name": "Empty",
      "level": 0
    },
    {
      "x": -2,
      "y": 18,
      "z": 0,
      "name": "Empty",
      "level": 0
    },
    {
      "x": -2,
      "y": 21,
      "z": 0,
      "name": "Empty",
      "level": 0
    },
    {
      "x": -2,
      "y": 9,
      "z": 1,
      "name": "Empty",
      "level": 0
    },
    {
      "x": -2,
      "y": 12,
      "z": 1,
      "name": "Empty",
      "level": 0
    },
    {
      "x": -2,
      "y": 17,
      "z": 1,
      "name": "Empty",
      "level": 0
    },
    {
      "x": -2,
      "y": 18,
      "z": 1,
      "name": "Empty",
      "level": 0
    },
    {
      "x": -2,
      "y": 21,
      "z": 1,
      "name": "Empty",
      "level": 0
    },
    {
      "x": -2,
      "y": 22,
      "z": 1,
      "name": "Empty",
      "level": 0
    },
    {
      "x": -2,
      "y": 18,
      "z": 2,
      "name": "Empty",
      "level": 0
    },
    {
      "x": -2,
      "y": 20,
      "z": 2,
      "name": "Empty",
      "level": 0
    },
    {
      "x": -1,
      "y": 13,
      "z": -1,
      "name": "Empty",
      "level": 0
    },
    {
      "x": -1,
      "y": 19,
      "z": -1,
      "name": "Empty",
      "level": 0
    },
    {
      "x": -1,
      "y": 9,
      "z": 0,
      "name": "Empty",
      "level": 0
    },
    {
      "x": -1,
      "y": 13,
      "z": 0,
      "name": "Empty",
      "level": 0
    },
    {
      "x": -1,
      "y": 21,
      "z": 0,
      "name": "Empty",
      "level": 0
    },
    {
      "x": -1,
      "y": 9,
      "z": 1,
      "name": "Empty",
      "level": 0
    },
    {
      "x": -1,
      "y": 10,
      "z": 1,
      "name": "Empty",
      "level": 0
    },
    {
      "x": -1,
      "y": 12,
      "z": 1,
      "name": "Empty",
      "level": 0
    },
    {
      "x": -1,
      "y": 13,
      "z": 1,
      "name": "Empty",
      "level": 0
    },
    {
      "x": -1,
      "y": 18,
      "z": 1,
      "name": "Empty",
      "level": 0
    },
    {
      "x": -1,
      "y": 21,
      "z": 1,
      "name": "Empty",
      "level": 0
    },
    {
      "x": -1,
      "y": 22,
      "z": 1,
      "name": "Empty",
      "level": 0
    },
    {
      "x": -1,
      "y": 9,
      "z": 2,
      "name": "Empty",
      "level": 0
    },
    {
      "x": -1,
      "y": 12,
      "z": 2,
      "name": "Empty",
      "level": 0
    },
    {
      "x": -1,
      "y": 18,
      "z": 2,
      "name": "Empty",
      "level": 0
    },
    {
      "x": -1,
      "y": 20,
      "z": 2,
      "name": "Empty",
      "level": 0
    },
    {
      "x": -1,
      "y": 21,
      "z": 2,
      "name": "Empty",
      "level": 0
    },
    {
      "x": -1,
      "y": 20,
      "z": 3,
      "name": "Empty",
      "level": 0
    },
    {
      "x": -1,
      "y": 21,
      "z": 3,
      "name": "Empty",
      "level": 0
    },
    {
      "x": 0,
      "y": 12,
      "z": -4,
      "name": "Empty",
      "level": 0
    },
    {
      "x": 0,
      "y": 12,
      "z": -3,
      "name": "Empty",
      "level": 0
    },
    {
      "x": 0,
      "y": 12,
      "z": -2,
      "name": "Empty",
      "level": 0
    },
    {
      "x": 0,
      "y": 16,
      "z": -2,
      "name": "Empty",
      "level": 0
    },
    {
      "x": 0,
      "y": 19,
      "z": -2,
      "name": "Empty",
      "level": 0
    },
    {
      "x": 0,
      "y": 13,
      "z": -1,
      "name": "Empty",
      "level": 0
    },
    {
      "x": 0,
      "y": 19,
      "z": -1,
      "name": "Empty",
      "level": 0
    },
    {
      "x": 0,
      "y": 19,
      "z": 0,
      "name": "Empty",
      "level": 0
    },
    {
      "x": 0,
      "y": 22,
      "z": 0,
      "name": "Empty",
      "level": 0
    },
    {
      "x": 0,
      "y": 23,
      "z": 0,
      "name": "Empty",
      "level": 0
    },
    {
      "x": 0,
      "y": 9,
      "z": 1,
      "name": "Empty",
      "level": 0
    },
    {
      "x": 0,
      "y": 12,
      "z": 1,
      "name": "Empty",
      "level": 0
    },
    {
      "x": 0,
      "y": 15,
      "z": 1,
      "name": "Empty",
      "level": 0
    },
    {
      "x": 0,
      "y": 18,
      "z": 1,
      "name": "Empty",
      "level": 0
    },
    {
      "x": 0,
      "y": 21,
      "z": 1,
      "name": "Empty",
      "level": 0
    },
    {
      "x": 0,
      "y": 22,
      "z": 1,
      "name": "Empty",
      "level": 0
    },
    {
      "x": 0,
      "y": 23,
      "z": 1,
      "name": "Empty",
      "level": 0
    },
    {
      "x": 0,
      "y": 9,
      "z": 2,
      "name": "Empty",
      "level": 0
    },
    {
      "x": 0,
      "y": 23,
      "z": 2,
      "name": "Empty",
      "level": 0
    },
    {
      "x": 0,
      "y": 11,
      "z": 3,
      "name": "Empty",
      "level": 0
    },
    {
      "x": 0,
      "y": 16,
      "z": 3,
      "name": "Empty",
      "level": 0
    },
    {
      "x": 0,
      "y": 22,
      "z": 3,
      "name": "Empty",
      "level": 0
    },
    {
      "x": 0,
      "y": 11,
      "z": 4,
      "name": "Empty",
      "level": 0
    },
    {
      "x": 0,
      "y": 20,
      "z": 4,
      "name": "Empty",
      "level": 0
    },
    {
      "x": 1,
      "y": 12,
      "z": -4,
      "name": "Empty",
      "level": 0
    },
    {
      "x": 1,
      "y": 12,
      "z": -3,
      "name": "Empty",
      "level": 0
    },
    {
      "x": 1,
      "y": 13,
      "z": -3,
      "name": "Empty",
      "level": 0
    },
    {
      "x": 1,
      "y": 15,
      "z": -3,
      "name": "Empty",
      "level": 0
    },
    {
      "x": 1,
      "y": 10,
      "z": -2,
      "name": "Empty",
      "level": 0
    },
    {
      "x": 1,
      "y": 12,
      "z": -2,
      "name": "Empty",
      "level": 0
    },
    {
      "x": 1,
      "y": 13,
      "z": -2,
      "name": "Empty",
      "level": 0
    },
    {
      "x": 1,
      "y": 16,
      "z": -2,
      "name": "Empty",
      "level": 0
    },
    {
      "x": 1,
      "y": 19,
      "z": -2,
      "name": "Empty",
      "level": 0
    },
    {
      "x": 1,
      "y": 10,
      "z": -1,
      "name": "Empty",
      "level": 0
    },
    {
      "x": 1,
      "y": 11,
      "z": -1,
      "name": "Empty",
      "level": 0
    },
    {
      "x": 1,
      "y": 12,
      "z": -1,
      "name": "Empty",
      "level": 0
    },
    {
      "x": 1,
      "y": 15,
      "z": -1,
      "name": "Empty",
      "level": 0
    },
    {
      "x": 1,
      "y": 16,
      "z": -1,
      "name": "Empty",
      "level": 0
    },
    {
      "x": 1,
      "y": 19,
      "z": -1,
      "name": "Empty",
      "level": 0
    },
    {
      "x": 1,
      "y": 20,
      "z": -1,
      "name": "Empty",
      "level": 0
    },
    {
      "x": 1,
      "y": 22,
      "z": -1,
      "name": "Empty",
      "level": 0
    },
    {
      "x": 1,
      "y": 23,
      "z": -1,
      "name": "Empty",
      "level": 0
    },
    {
      "x": 1,
      "y": 10,
      "z": 0,
      "name": "Empty",
      "level": 0
    },
    {
      "x": 1,
      "y": 12,
      "z": 0,
      "name": "Empty",
      "level": 0
    },
    {
      "x": 1,
      "y": 14,
      "z": 0,
      "name": "Empty",
      "level": 0
    },
    {
      "x": 1,
      "y": 15,
      "z": 0,
      "name": "Empty",
      "level": 0
    },
    {
      "x": 1,
      "y": 16,
      "z": 0,
      "name": "Empty",
      "level": 0
    },
    {
      "x": 1,
      "y": 19,
      "z": 0,
      "name": "Empty",
      "level": 0
    },
    {
      "x": 1,
      "y": 22,
      "z": 0,
      "name": "Empty",
      "level": 0
    },
    {
      "x": 1,
      "y": 0,
      "z": 1,
      "name": "Empty",
      "level": 0
    },
    {
      "x": 1,
      "y": 1,
      "z": 1,
      "name": "Empty",
      "level": 0
    },
    {
      "x": 1,
      "y": 2,
      "z": 1,
      "name": "Empty",
      "level": 0
    },
    {
      "x": 1,
      "y": 3,
      "z": 1,
      "name": "Empty",
      "level": 0
    },
    {
      "x": 1,
      "y": 4,
      "z": 1,
      "name": "Empty",
      "level": 0
    },
    {
      "x": 1,
      "y": 5,
      "z": 1,
      "name": "Empty",
      "level": 0
    },
    {
      "x": 1,
      "y": 6,
      "z": 1,
      "name": "Empty",
      "level": 0
    },
    {
      "x": 1,
      "y": 7,
      "z": 1,
      "name": "Empty",
      "level": 0
    },
    {
      "x": 1,
      "y": 8,
      "z": 1,
      "name": "Empty",
      "level": 0
    },
    {
      "x": 1,
      "y": 9,
      "z": 1,
      "name": "Empty",
      "level": 0
    },
    {
      "x": 1,
      "y": 10,
      "z": 1,
      "name": "Empty",
      "level": 0
    },
    {
      "x": 1,
      "y": 11,
      "z": 1,
      "name": "Empty",
      "level": 0
    },
    {
      "x": 1,
      "y": 12,
      "z": 1,
      "name": "Empty",
      "level": 0
    },
    {
      "x": 1,
      "y": 13,
      "z": 1,
      "name": "Empty",
      "level": 0
    },
    {
      "x": 1,
      "y": 14,
      "z": 1,
      "name": "Empty",
      "level": 0
    },
    {
      "x": 1,
      "y": 15,
      "z": 1,
      "name": "Empty",
      "level": 0
    },
    {
      "x": 1,
      "y": 16,
      "z": 1,
      "name": "Empty",
      "level": 0
    },
    {
      "x": 1,
      "y": 17,
      "z": 1,
      "name": "Empty",
      "level": 0
    },
    {
      "x": 1,
      "y": 18,
      "z": 1,
      "name": "Empty",
      "level": 0
    },
    {
      "x": 1,
      "y": 19,
      "z": 1,
      "name": "Empty",
      "level": 0
    },
    {
      "x": 1,
      "y": 20,
      "z": 1,
      "name": "Empty",
      "level": 0
    },
    {
      "x": 1,
      "y": 21,
      "z": 1,
      "name": "Empty",
      "level": 0
    },
    {
      "x": 1,
      "y": 22,
      "z": 1,
      "name": "Empty",
      "level": 0
    },
    {
      "x": 1,
      "y": 23,
      "z": 1,
      "name": "Empty",
      "level": 0
    },
    {
      "x": 1,
      "y": 24,
      "z": 1,
      "name": "Empty",
      "level": 0
    },
    {
      "x": 1,
      "y": 6,
      "z": 2,
      "name": "Empty",
      "level": 0
    },
    {
      "x": 1,
      "y": 11,
      "z": 2,
      "name": "Empty",
      "level": 0
    },
    {
      "x": 1,
      "y": 15,
      "z": 2,
      "name": "Empty",
      "level": 0
    },
    {
      "x": 1,
      "y": 16,
      "z": 2,
      "name": "Empty",
      "level": 0
    },
    {
      "x": 1,
      "y": 20,
      "z": 2,
      "name": "Empty",
      "level": 0
    },
    {
      "x": 1,
      "y": 22,
      "z": 2,
      "name": "Empty",
      "level": 0
    },
    {
      "x": 1,
      "y": 23,
      "z": 2,
      "name": "Empty",
      "level": 0
    },
    {
      "x": 1,
      "y": 11,
      "z": 3,
      "name": "Empty",
      "level": 0
    },
    {
      "x": 1,
      "y": 12,
      "z": 3,
      "name": "Empty",
      "level": 0
    },
    {
      "x": 1,
      "y": 15,
      "z": 3,
      "name": "Empty",
      "level": 0
    },
    {
      "x": 1,
      "y": 16,
      "z": 3,
      "name": "Empty",
      "level": 0
    },
    {
      "x": 1,
      "y": 17,
      "z": 3,
      "name": "Empty",
      "level": 0
    },
    {
      "x": 1,
      "y": 20,
      "z": 3,
      "name": "Empty",
      "level": 0
    },
    {
      "x": 1,
      "y": 21,
      "z": 3,
      "name": "Empty",
      "level": 0
    },
    {
      "x": 1,
      "y": 22,
      "z": 3,
      "name": "Empty",
      "level": 0
    },
    {
      "x": 1,
      "y": 11,
      "z": 4,
      "name": "Empty",
      "level": 0
    },
    {
      "x": 1,
      "y": 16,
      "z": 4,
      "name": "Empty",
      "level": 0
    },
    {
      "x": 1,
      "y": 20,
      "z": 4,
      "name": "Empty",
      "level": 0
    },
    {
      "x": 1,
      "y": 21,
      "z": 4,
      "name": "Empty",
      "level": 0
    },
    {
      "x": 2,
      "y": 12,
      "z": -3,
      "name": "Empty",
      "level": 0
    },
    {
      "x": 2,
      "y": 16,
      "z": -3,
      "name": "Empty",
      "level": 0
    },
    {
      "x": 2,
      "y": 10,
      "z": -2,
      "name": "Empty",
      "level": 0
    },
    {
      "x": 2,
      "y": 12,
      "z": -2,
      "name": "Empty",
      "level": 0
    },
    {
      "x": 2,
      "y": 16,
      "z": -2,
      "name": "Empty",
      "level": 0
    },
    {
      "x": 2,
      "y": 10,
      "z": -1,
      "name": "Empty",
      "level": 0
    },
    {
      "x": 2,
      "y": 15,
      "z": -1,
      "name": "Empty",
      "level": 0
    },
    {
      "x": 2,
      "y": 19,
      "z": -1,
      "name": "Empty",
      "level": 0
    },
    {
      "x": 2,
      "y": 22,
      "z": -1,
      "name": "Empty",
      "level": 0
    },
    {
      "x": 2,
      "y": 13,
      "z": 0,
      "name": "Empty",
      "level": 0
    },
    {
      "x": 2,
      "y": 15,
      "z": 0,
      "name": "Empty",
      "level": 0
    },
    {
      "x": 2,
      "y": 22,
      "z": 0,
      "name": "Empty",
      "level": 0
    },
    {
      "x": 2,
      "y": 5,
      "z": 1,
      "name": "Empty",
      "level": 0
    },
    {
      "x": 2,
      "y": 13,
      "z": 1,
      "name": "Empty",
      "level": 0
    },
    {
      "x": 2,
      "y": 18,
      "z": 1,
      "name": "Empty",
      "level": 0
    },
    {
      "x": 2,
      "y": 19,
      "z": 1,
      "name": "Empty",
      "level": 0
    },
    {
      "x": 2,
      "y": 22,
      "z": 1,
      "name": "Empty",
      "level": 0
    },
    {
      "x": 2,
      "y": 23,
      "z": 1,
      "name": "Empty",
      "level": 0
    },
    {
      "x": 2,
      "y": 22,
      "z": 2,
      "name": "Empty",
      "level": 0
    },
    {
      "x": 2,
      "y": 11,
      "z": 3,
      "name": "Empty",
      "level": 0
    },
    {
      "x": 2,
      "y": 13,
      "z": 3,
      "name": "Empty",
      "level": 0
    },
    {
      "x": 2,
      "y": 16,
      "z": 3,
      "name": "Empty",
      "level": 0
    },
    {
      "x": 2,
      "y": 20,
      "z": 3,
      "name": "Empty",
      "level": 0
    },
    {
      "x": 2,
      "y": 22,
      "z": 3,
      "name": "Empty",
      "level": 0
    },
    {
      "x": 2,
      "y": 11,
      "z": 4,
      "name": "Empty",
      "level": 0
    },
    {
      "x": 2,
      "y": 12,
      "z": 4,
      "name": "Empty",
      "level": 0
    },
    {
      "x": 2,
      "y": 20,
      "z": 4,
      "name": "Empty",
      "level": 0
    },
    {
      "x": 3,
      "y": 10,
      "z": -2,
      "name": "Empty",
      "level": 0
    },
    {
      "x": 3,
      "y": 10,
      "z": -1,
      "name": "Empty",
      "level": 0
    },
    {
      "x": 3,
      "y": 21,
      "z": -1,
      "name": "Empty",
      "level": 0
    },
    {
      "x": 3,
      "y": 13,
      "z": 0,
      "name": "Empty",
      "level": 0
    },
    {
      "x": 3,
      "y": 19,
      "z": 0,
      "name": "Empty",
      "level": 0
    },
    {
      "x": 3,
      "y": 13,
      "z": 1,
      "name": "Empty",
      "level": 0
    },
    {
      "x": 3,
      "y": 14,
      "z": 1,
      "name": "Empty",
      "level": 0
    },
    {
      "x": 3,
      "y": 18,
      "z": 1,
      "name": "Empty",
      "level": 0
    },
    {
      "x": 3,
      "y": 19,
      "z": 1,
      "name": "Empty",
      "level": 0
    },
    {
      "x": 3,
      "y": 13,
      "z": 2,
      "name": "Empty",
      "level": 0
    },
    {
      "x": 3,
      "y": 18,
      "z": 2,
      "name": "Empty",
      "level": 0
    },
    {
      "x": 4,
      "y": 19,
      "z": 0,
      "name": "Empty",
      "level": 0
    },
    {
      "x": 4,
      "y": 13,
      "z": 1,
      "name": "Empty",
      "level": 0
    },
    {
      "x": 4,
      "y": 19,
      "z": 1,
      "name": "Empty",
      "level": 0
    },
    {
      "x": 4,
      "y": 18,
      "z": 2,
      "name": "Empty",
      "level": 0
    }
  ]
}